Workbook

Sheet MONTLY Sales Report (Rev.1)
B1: MONTHLY SALES REPORT
B3: MONTH: DECEMBER-2023 | G3: SALES AMOUNT | I3: =SUM(G8:G107) -> 0
B4: From: 01/Dec/2023 To: 31/Dec/2023 | G4: DISCOUNT | I4: =SUM(H8:H107) -> 0
G5: SALES TOTAL | I5: =SUM(I8:I107) -> 0
B7: ITEM DESCRIPTION | C7: ITEM CATEGORY | D7: ITEM CODE | E7: PRICE (SRP) | F7: QTY | G7: SALES AMOUNT | H7: DISCOUNT | I7: SALES TOTAL | K7: REMARKS | L7: DATE (STOCK OUT)
C20: =IFERROR(VLOOKUP(B20,'Inventory List'!$B$3:$E$47,2,0),"–") -> – | D20: =IFERROR(VLOOKUP(B20,'Inventory List'!$B$3:$E$47,3,0),"–") -> – | E20: =IFERROR(VLOOKUP(B20,'Inventory List'!$B$3:$E$47,4,0),"–") -> – | G20: =IFERROR('MONTLY Sales Report (Rev.1)'!$E20*'MONTLY Sales Report (Rev.1)'!$F20,"") | I20: =IFERROR('MONTLY Sales Report (Rev.1)'!$G20-'MONTLY Sales Report (Rev.1)'!$H20,"")
C21: =IFERROR(VLOOKUP(B21,'Inventory List'!$B$3:$E$47,2,0),"–") -> – | D21: =IFERROR(VLOOKUP(B21,'Inventory List'!$B$3:$E$47,3,0),"–") -> – | E21: =IFERROR(VLOOKUP(B21,'Inventory List'!$B$3:$E$47,4,0),"–") -> – | G21: =IFERROR('MONTLY Sales Report (Rev.1)'!$E21*'MONTLY Sales Report (Rev.1)'!$F21,"") | I21: =IFERROR('MONTLY Sales Report (Rev.1)'!$G21-'MONTLY Sales Report (Rev.1)'!$H21,"")
C22: =IFERROR(VLOOKUP(B22,'Inventory List'!$B$3:$E$47,2,0),"–") -> – | D22: =IFERROR(VLOOKUP(B22,'Inventory List'!$B$3:$E$47,3,0),"–") -> – | E22: =IFERROR(VLOOKUP(B22,'Inventory List'!$B$3:$E$47,4,0),"–") -> – | G22: =IFERROR('MONTLY Sales Report (Rev.1)'!$E22*'MONTLY Sales Report (Rev.1)'!$F22,"") | I22: =IFERROR('MONTLY Sales Report (Rev.1)'!$G22-'MONTLY Sales Report (Rev.1)'!$H22,"")
C23: =IFERROR(VLOOKUP(B23,'Inventory List'!$B$3:$E$47,2,0),"–") -> – | D23: =IFERROR(VLOOKUP(B23,'Inventory List'!$B$3:$E$47,3,0),"–") -> – | E23: =IFERROR(VLOOKUP(B23,'Inventory List'!$B$3:$E$47,4,0),"–") -> – | G23: =IFERROR('MONTLY Sales Report (Rev.1)'!$E23*'MONTLY Sales Report (Rev.1)'!$F23,"") | I23: =IFERROR('MONTLY Sales Report (Rev.1)'!$G23-'MONTLY Sales Report (Rev.1)'!$H23,"")
C24: =IFERROR(VLOOKUP(B24,'Inventory List'!$B$3:$E$47,2,0),"–") -> – | D24: =IFERROR(VLOOKUP(B24,'Inventory List'!$B$3:$E$47,3,0),"–") -> – | E24: =IFERROR(VLOOKUP(B24,'Inventory List'!$B$3:$E$47,4,0),"–") -> – | G24: =IFERROR('MONTLY Sales Report (Rev.1)'!$E24*'MONTLY Sales Report (Rev.1)'!$F24,"") | I24: =IFERROR('MONTLY Sales Report (Rev.1)'!$G24-'MONTLY Sales Report (Rev.1)'!$H24,"")
C25: =IFERROR(VLOOKUP(B25,'Inventory List'!$B$3:$E$47,2,0),"–") -> – | D25: =IFERROR(VLOOKUP(B25,'Inventory List'!$B$3:$E$47,3,0),"–") -> – | E25: =IFERROR(VLOOKUP(B25,'Inventory List'!$B$3:$E$47,4,0),"–") -> – | G25: =IFERROR('MONTLY Sales Report (Rev.1)'!$E25*'MONTLY Sales Report (Rev.1)'!$F25,"") | I25: =IFERROR('MONTLY Sales Report (Rev.1)'!$G25-'MONTLY Sales Report (Rev.1)'!$H25,"")
C26: =IFERROR(VLOOKUP(B26,'Inventory List'!$B$3:$E$47,2,0),"–") -> – | D26: =IFERROR(VLOOKUP(B26,'Inventory List'!$B$3:$E$47,3,0),"–") -> – | E26: =IFERROR(VLOOKUP(B26,'Inventory List'!$B$3:$E$47,4,0),"–") -> – | G26: =IFERROR('MONTLY Sales Report (Rev.1)'!$E26*'MONTLY Sales Report (Rev.1)'!$F26,"") | I26: =IFERROR('MONTLY Sales Report (Rev.1)'!$G26-'MONTLY Sales Report (Rev.1)'!$H26,"")
C27: =IFERROR(VLOOKUP(B27,'Inventory List'!$B$3:$E$47,2,0),"–") -> – | D27: =IFERROR(VLOOKUP(B27,'Inventory List'!$B$3:$E$47,3,0),"–") -> – | E27: =IFERROR(VLOOKUP(B27,'Inventory List'!$B$3:$E$47,4,0),"–") -> – | G27: =IFERROR('MONTLY Sales Report (Rev.1)'!$E27*'MONTLY Sales Report (Rev.1)'!$F27,"") | I27: =IFERROR('MONTLY Sales Report (Rev.1)'!$G27-'MONTLY Sales Report (Rev.1)'!$H27,"")
C28: =IFERROR(VLOOKUP(B28,'Inventory List'!$B$3:$E$47,2,0),"–") -> – | D28: =IFERROR(VLOOKUP(B28,'Inventory List'!$B$3:$E$47,3,0),"–") -> – | E28: =IFERROR(VLOOKUP(B28,'Inventory List'!$B$3:$E$47,4,0),"–") -> – | G28: =IFERROR('MONTLY Sales Report (Rev.1)'!$E28*'MONTLY Sales Report (Rev.1)'!$F28,"") | I28: =IFERROR('MONTLY Sales Report (Rev.1)'!$G28-'MONTLY Sales Report (Rev.1)'!$H28,"")
C29: =IFERROR(VLOOKUP(B29,'Inventory List'!$B$3:$E$47,2,0),"–") -> – | D29: =IFERROR(VLOOKUP(B29,'Inventory List'!$B$3:$E$47,3,0),"–") -> – | E29: =IFERROR(VLOOKUP(B29,'Inventory List'!$B$3:$E$47,4,0),"–") -> – | G29: =IFERROR('MONTLY Sales Report (Rev.1)'!$E29*'MONTLY Sales Report (Rev.1)'!$F29,"") | I29: =IFERROR('MONTLY Sales Report (Rev.1)'!$G29-'MONTLY Sales Report (Rev.1)'!$H29,"")
C30: =IFERROR(VLOOKUP(B30,'Inventory List'!$B$3:$E$47,2,0),"–") -> – | D30: =IFERROR(VLOOKUP(B30,'Inventory List'!$B$3:$E$47,3,0),"–") -> – | E30: =IFERROR(VLOOKUP(B30,'Inventory List'!$B$3:$E$47,4,0),"–") -> – | G30: =IFERROR('MONTLY Sales Report (Rev.1)'!$E30*'MONTLY Sales Report (Rev.1)'!$F30,"") | I30: =IFERROR('MONTLY Sales Report (Rev.1)'!$G30-'MONTLY Sales Report (Rev.1)'!$H30,"")
C31: =IFERROR(VLOOKUP(B31,'Inventory List'!$B$3:$E$47,2,0),"–") -> – | D31: =IFERROR(VLOOKUP(B31,'Inventory List'!$B$3:$E$47,3,0),"–") -> – | E31: =IFERROR(VLOOKUP(B31,'Inventory List'!$B$3:$E$47,4,0),"–") -> – | G31: =IFERROR('MONTLY Sales Report (Rev.1)'!$E31*'MONTLY Sales Report (Rev.1)'!$F31,"") | I31: =IFERROR('MONTLY Sales Report (Rev.1)'!$G31-'MONTLY Sales Report (Rev.1)'!$H31,"")
... C107: =IFERROR(VLOOKUP(B107,'Inventory List'!$B$3:$E$47,2,0),"–") -> – | D107: =IFERROR(VLOOKUP(B107,'Inventory List'!$B$3:$E$47,3,0),"–") -> – | E107: =IFERROR(VLOOKUP(B107,'Inventory List'!$B$3:$E$47,4,0),"–") -> – | G107: =IFERROR('MONTLY Sales Report (Rev.1)'!$E107*'MONTLY Sales Report (Rev.1)'!$F107,"") | I107: =IFERROR('MONTLY Sales Report (Rev.1)'!$G107-'MONTLY Sales Report (Rev.1)'!$H107,"")

Sheet Inventory List
B1: INVENTORY LIST
B2: ITEM DESCRIPTION | C2: ITEM CATEGORY | D2: ITEM CODE | E2: PRICE
B3: 5 GAL SLIM CONTAINER W/ CAP BLUE-WOW - NEW BATCH (5/15/26) | C3: CONTAINERS | D3: 10-150-105 | E3: 145
B4: 5 GAL SLIM CONTAINER W/ CAP GREEN | C4: CONTAINERS | D4: 10-150-105 | E4: 140
B5: 5 GAL SLIM CONTAINER W/ CAP GREEN | C5: CONTAINERS | D5: 10-150-105 | E5: 135
B6: 5 GAL SLIM CONTAINER W/ CAP YELLOW | C6: CONTAINERS | D6: 10-150-105 | E6: 140
B7: 5 GAL (PET) ROUND CONTAINER BLUE W/ CAP (CLASS A) (SOLD) | C7: CONTAINERS | D7: 10-110-103 | E7: 130
B8: 5 GAL (PET) ROUND CONTAINER BLUE W/ CAP (CLASS A) - NEW BATCH (5/15/26) | C8: CONTAINERS | D8: 10-110-103/10-120-103 | E8: 150
B9: 5 GAL SLIM CONTAINER W/ CAP BLUE (SOLD) | C9: CONTAINERS | D9: 10-150-105 | E9: 135
B10: 5 GAL SLIM CONTAINER W/ CAP BLUE-WOW - NEW BATCH (5/15/26) | C10: CONTAINERS | D10: 10-150-105 | E10: 145
B11: 5 GAL SLIM CONTAINER W/ CAP GREEN | C11: CONTAINERS | D11: 10-150-105 | E11: 140
B12: 5 GAL SLIM CONTAINER W/ CAP GREEN | C12: CONTAINERS | D12: 10-150-105 | E12: 135
B13: 5 GAL SLIM CONTAINER W/ CAP YELLOW | C13: CONTAINERS | D13: 10-150-105 | E13: 140
B14: 5 GAL (PET) ROUND CONTAINER BLUE W/ CAP (CLASS A) (SOLD) | C14: CONTAINERS | D14: 10-110-103 | E14: 130
... B17: SMALL CAP SEAL FOR SLIM LW | C17: CAPSEALS | D17: 10-190-101 | E17: 115
B18: FAUCET SEAL FOR SLIM LW | C18: CAPSEALS | E18: 170
B19: FAUCET SEAL FOR SLIM LW (CLASS B) | C19: CAPSEALS | E19: 170
B20: UMBRELLA SEAL FOR ROUND LW | C20: CAPSEALS | D20: 10-220-101 | E20: 130
B21: UMBRELLA SEAL FOR ROUND LW (CLASS B) | C21: CAPSEALS | E21: 130
B22: BIG CAP SEAL FOR SLIM GENERIC (SOLD) | C22: CAPSEALS | D22: 10-100-107 | E22: 120
B23: SMALL CAP SEAL FOR SLIM GENERIC | C23: CAPSEALS | D23: 10-190-107 | E23: 110
B24: FAUCET SEAL FOR SLIM GENERIC (SOLD) | C24: CAPSEALS | D24: 10-140-107 | E24: 170
B25: FAUCET SEAL FOR SLIM GENERIC - NEW BATCH (5/15/26) | C25: CAPSEALS | D25: 10-140-107 | E25: 180
B26: UMBRELLA SEAL FOR ROUND GENERIC | C26: CAPSEALS | D26: 10-220-107 | E26: 125
B27: BIG CAP SEAL FOR SLIM LW | C27: CAPSEALS | D27: 10-100-102 | E27: 130
B28: SMALL CAP SEAL FOR SLIM LW | C28: CAPSEALS | D28: 10-190-101 | E28: 115
B29: FAUCET SEAL FOR SLIM LW | C29: CAPSEALS | E29: 170
B30: FAUCET SEAL FOR SLIM LW (CLASS B) | C30: CAPSEALS | E30: 170
B31: UMBRELLA SEAL FOR ROUND LW | C31: CAPSEALS | D31: 10-220-101 | E31: 130
B32: UMBRELLA SEAL FOR ROUND LW (CLASS B) | C32: CAPSEALS | E32: 130
B33: BIG CAP SEAL FOR SLIM GENERIC (SOLD) | C33: CAPSEALS | D33: 10-100-107 | E33: 120
B34: SMALL CAP SEAL FOR SLIM GENERIC | C34: CAPSEALS | D34: 10-190-107 | E34: 110
B35: FAUCET SEAL FOR SLIM GENERIC (SOLD) | C35: CAPSEALS | D35: 10-140-107 | E35: 170
B36: FAUCET SEAL FOR SLIM GENERIC - NEW BATCH (5/15/26) | C36: CAPSEALS | D36: 10-140-107 | E36: 180
B37: UMBRELLA SEAL FOR ROUND GENERIC | C37: CAPSEALS | D37: 10-220-107 | E37: 125
B38: 1 L SOAP SANITIZER | C38: SOAP SANITIZER | D38: 25-120-101 | E38: 65
B39: SOAP SANITIZER: SOAP WOW-1LITER - NEW BATCH (5/15/26) | C39: SOAP SANITIZER | D39: 25-420-101 | E39: 80
B40: 1 L SOAP SANITIZER | C40: SOAP SANITIZER | D40: 25-120-101 | E40: 65
B41: SOAP SANITIZER: SOAP WOW-1LITER - NEW BATCH (5/15/26) | C41: SOAP SANITIZER | D41: 25-420-101 | E41: 80
B42: AUSTRALIAN SALT (SOLD) | C42: SALT 50KG | D42: 19-150-100 | E42: 520
...
