Workbook

Sheet Dashboard
A1: DASHBOARD
A3: Total catalog items | C3: =COUNTA('Item Catalog'!$A$3:$A$1000) -> 51
A4: Items — In Stock | C4: =COUNTIF('Item Catalog'!$O$3:$O$1000,"In Stock") -> 46
A5: Items — Low | C5: =COUNTIF('Item Catalog'!$O$3:$O$1000,"Low") -> 0
A6: Items — Out | C6: =COUNTIF('Item Catalog'!$O$3:$O$1000,"Out") -> 5
A8: Total Qty Ordered (all-time) | C8: =SUM('Item Catalog'!$L$3:$L$1000) -> 6771
A9: Total Qty Stock Out (all-time) | C9: =SUM('Item Catalog'!$M$3:$M$1000) -> 2606
A10: Total Qty Balance (current stock, all items) | C10: =SUM('Item Catalog'!$N$3:$N$1000) -> 4165
A12: Total spent on restocking to date | C12: ='Restock Orders'!$F$13 -> 522564
A14: Sales this period (Source = Sales Entry only) | C14: =SUMPRODUCT(('Stock Movements'!$G$3:$G$1000="Sales Entry")*('Stock Movements'!$D$3:$D$1000="Out")*('Stock Movements'!$E$3:$E$1000)) -> 0
A16: Note: "Sales this period" only counts Stock Movements rows tagged Source = "Sales Entry" (i.e. real, dated retail sales logged going forward by the app). It reads 0 right now because the historical import rows are tagged "Historical Import", not "Sales Entry" — no per-transaction sales history survives from the original file (see spec, item 11.2). Yearly Sales totals for past years should be computed by the app directly from its own Sales Report data, not from this workbook.

Sheet Item Catalog
A1: ITEM CATALOG (single shared master list)
A2: Item ID | B2: Item Label | C2: Item Name | D2: Code | E2: Category | F2: Packing | G2: Batch Note | H2: Batch Date | I2: Dealer Price | J2: SRP | K2: Low Stock Threshold | L2: Qty Ordered | M2: Qty Stock Out | N2: Qty Balance | O2: Status | P2: Profit / Unit
A3: ITM-001 | B3: =A3&" · "&C3 -> ITM-001 · 5 GAL SLIM CONTAINER W/ CAP BLUE | C3: 5 GAL SLIM CONTAINER W/ CAP BLUE | D3: 10-150-105 | E3: CONTAINERS | F3: 1 PC | G3: SOLD | I3: 105 | J3: 135 | L3: =SUMIFS('Stock Movements'!$E:$E,'Stock Movements'!$C:$C,$B3,'Stock Movements'!$D:$D,"In") -> 526 | M3: =SUMIFS('Stock Movements'!$E:$E,'Stock Movements'!$C:$C,$B3,'Stock Movements'!$D:$D,"Out") -> 526 | N3: =L3-M3 -> 0 | O3: =IF(N3<=0,"Out",IF(AND(K3<>"",N3<=K3),"Low","In Stock")) -> Out | P3: =J3-I3 -> 30
A4: ITM-002 | B4: =A4&" · "&C4 -> ITM-002 · 5 GAL SLIM CONTAINER W/ CAP BLUE-WOW | C4: 5 GAL SLIM CONTAINER W/ CAP BLUE-WOW | D4: 10-150-105 | E4: CONTAINERS | F4: 1 PC | G4: NEW BATCH | H4: 5/15/26 | I4: 110 | J4: 145 | L4: =SUMIFS('Stock Movements'!$E:$E,'Stock Movements'!$C:$C,$B4,'Stock Movements'!$D:$D,"In") -> 200 | M4: =SUMIFS('Stock Movements'!$E:$E,'Stock Movements'!$C:$C,$B4,'Stock Movements'!$D:$D,"Out") -> 53 | N4: =L4-M4 -> 147 | O4: =IF(N4<=0,"Out",IF(AND(K4<>"",N4<=K4),"Low","In Stock")) -> In Stock | P4: =J4-I4 -> 35
A5: ITM-003 | B5: =A5&" · "&C5 -> ITM-003 · 5 GAL SLIM CONTAINER W/ CAP GREEN | C5: 5 GAL SLIM CONTAINER W/ CAP GREEN | D5: 10-150-105 | E5: CONTAINERS | F5: 1 PC | I5: 105 | J5: 140 | L5: =SUMIFS('Stock Movements'!$E:$E,'Stock Movements'!$C:$C,$B5,'Stock Movements'!$D:$D,"In") -> 350 | M5: =SUMIFS('Stock Movements'!$E:$E,'Stock Movements'!$C:$C,$B5,'Stock Movements'!$D:$D,"Out") -> 220 | N5: =L5-M5 -> 130 | O5: =IF(N5<=0,"Out",IF(AND(K5<>"",N5<=K5),"Low","In Stock")) -> In Stock | P5: =J5-I5 -> 35
A6: ITM-004 | B6: =A6&" · "&C6 -> ITM-004 · 5 GAL SLIM CONTAINER W/ CAP YELLOW | C6: 5 GAL SLIM CONTAINER W/ CAP YELLOW | D6: 10-150-105 | E6: CONTAINERS | F6: 1 PC | I6: 105 | J6: 140 | L6: =SUMIFS('Stock Movements'!$E:$E,'Stock Movements'!$C:$C,$B6,'Stock Movements'!$D:$D,"In") -> 350 | M6: =SUMIFS('Stock Movements'!$E:$E,'Stock Movements'!$C:$C,$B6,'Stock Movements'!$D:$D,"Out") -> 58 | N6: =L6-M6 -> 292 | O6: =IF(N6<=0,"Out",IF(AND(K6<>"",N6<=K6),"Low","In Stock")) -> In Stock | P6: =J6-I6 -> 35
A7: ITM-005 | B7: =A7&" · "&C7 -> ITM-005 · 5 GAL (PET) ROUND CONTAINER BLUE W/ CAP (CLASS A) | C7: 5 GAL (PET) ROUND CONTAINER BLUE W/ CAP (CLASS A) | D7: 10-110-103 | E7: CONTAINERS | F7: 1 PC | G7: SOLD | I7: 112 | J7: 130 | L7: =SUMIFS('Stock Movements'!$E:$E,'Stock Movements'!$C:$C,$B7,'Stock Movements'!$D:$D,"In") -> 200 | M7: =SUMIFS('Stock Movements'!$E:$E,'Stock Movements'!$C:$C,$B7,'Stock Movements'!$D:$D,"Out") -> 199 | N7: =L7-M7 -> 1 | O7: =IF(N7<=0,"Out",IF(AND(K7<>"",N7<=K7),"Low","In Stock")) -> In Stock | P7: =J7-I7 -> 18
A8: ITM-006 | B8: =A8&" · "&C8 -> ITM-006 · 5 GAL (PET) ROUND CONTAINER BLUE W/ CAP (CLASS A) | C8: 5 GAL (PET) ROUND CONTAINER BLUE W/ CAP (CLASS A) | D8: 10-110-103/10-120-103 | E8: CONTAINERS | G8: NEW BATCH | H8: 5/15/26 | I8: 116.7 | J8: 150 | L8: =SUMIFS('Stock Movements'!$E:$E,'Stock Movements'!$C:$C,$B8,'Stock Movements'!$D:$D,"In") -> 100 | M8: =SUMIFS('Stock Movements'!$E:$E,'Stock Movements'!$C:$C,$B8,'Stock Movements'!$D:$D,"Out") -> 11 | N8: =L8-M8 -> 89 | O8: =IF(N8<=0,"Out",IF(AND(K8<>"",N8<=K8),"Low","In Stock")) -> In Stock | P8: =J8-I8 -> 33.3
A9: ITM-007 | B9: =A9&" · "&C9 -> ITM-007 · BIG CAP SEAL FOR SLIM LW | C9: BIG CAP SEAL FOR SLIM LW | D9: 10-100-102 | E9: CAPSEALS | F9: 500 PC | I9: 100 | J9: 130 | L9: =SUMIFS('Stock Movements'!$E:$E,'Stock Movements'!$C:$C,$B9,'Stock Movements'!$D:$D,"In") -> 100 | M9: =SUMIFS('Stock Movements'!$E:$E,'Stock Movements'!$C:$C,$B9,'Stock Movements'!$D:$D,"Out") -> 55 | N9: =L9-M9 -> 45 | O9: =IF(N9<=0,"Out",IF(AND(K9<>"",N9<=K9),"Low","In Stock")) -> In Stock | P9: =J9-I9 -> 30
A10: ITM-008 | B10: =A10&" · "&C10 -> ITM-008 · SMALL CAP SEAL FOR SLIM LW | C10: SMALL CAP SEAL FOR SLIM LW | D10: 10-190-101 | E10: CAPSEALS | F10: 1000 PC | I10: 70 | J10: 115 | L10: =SUMIFS('Stock Movements'!$E:$E,'Stock Movements'!$C:$C,$B10,'Stock Movements'!$D:$D,"In") -> 100 | M10: =SUMIFS('Stock Movements'!$E:$E,'Stock Movements'!$C:$C,$B10,'Stock Movements'!$D:$D,"Out") -> 24 | N10: =L10-M10 -> 76 | O10: =IF(N10<=0,"Out",IF(AND(K10<>"",N10<=K10),"Low","In Stock")) -> In Stock | P10: =J10-I10 -> 45
A11: ITM-009 | B11: =A11&" · "&C11 -> ITM-009 · FAUCET SEAL FOR SLIM LW | C11: FAUCET SEAL FOR SLIM LW | E11: CAPSEALS | F11: 1000 PC | I11: 100 | J11: 170 | L11: =SUMIFS('Stock Movements'!$E:$E,'Stock Movements'!$C:$C,$B11,'Stock Movements'!$D:$D,"In") -> 100 | M11: =SUMIFS('Stock Movements'!$E:$E,'Stock Movements'!$C:$C,$B11,'Stock Movements'!$D:$D,"Out") -> 62 | N11: =L11-M11 -> 38 | O11: =IF(N11<=0,"Out",IF(AND(K11<>"",N11<=K11),"Low","In Stock")) -> In Stock | P11: =J11-I11 -> 70
A12: ITM-010 | B12: =A12&" · "&C12 -> ITM-010 · FAUCET SEAL FOR SLIM LW (CLASS B) | C12: FAUCET SEAL FOR SLIM LW (CLASS B) | E12: CAPSEALS | F12: 1000 PC | I12: 95 | J12: 170 | L12: =SUMIFS('Stock Movements'!$E:$E,'Stock Movements'!$C:$C,$B12,'Stock Movements'!$D:$D,"In") -> 25 | M12: =SUMIFS('Stock Movements'!$E:$E,'Stock Movements'!$C:$C,$B12,'Stock Movements'!$D:$D,"Out") -> 0 | N12: =L12-M12 -> 25 | O12: =IF(N12<=0,"Out",IF(AND(K12<>"",N12<=K12),"Low","In Stock")) -> In Stock | P12: =J12-I12 -> 75
A13: ITM-011 | B13: =A13&" · "&C13 -> ITM-011 · UMBRELLA SEAL FOR ROUND LW | C13: UMBRELLA SEAL FOR ROUND LW | D13: 10-220-101 | E13: CAPSEALS | F13: 500 PC | I13: 100 | J13: 130 | L13: =SUMIFS('Stock Movements'!$E:$E,'Stock Movements'!$C:$C,$B13,'Stock Movements'!$D:$D,"In") -> 100 | M13: =SUMIFS('Stock Movements'!$E:$E,'Stock Movements'!$C:$C,$B13,'Stock Movements'!$D:$D,"Out") -> 33 | N13: =L13-M13 -> 67 | O13: =IF(N13<=0,"Out",IF(AND(K13<>"",N13<=K13),"Low","In Stock")) -> In Stock | P13: =J13-I13 -> 30
A14: ITM-012 | B14: =A14&" · "&C14 -> ITM-012 · UMBRELLA SEAL FOR ROUND LW (CLASS B) | C14: UMBRELLA SEAL FOR ROUND LW (CLASS B) | E14: CAPSEALS | F14: 500 PC | I14: 95 | J14: 130 | L14: =SUMIFS('Stock Movements'!$E:$E,'Stock Movements'!$C:$C,$B14,'Stock Movements'!$D:$D,"In") -> 50 | M14: =SUMIFS('Stock Movements'!$E:$E,'Stock Movements'!$C:$C,$B14,'Stock Movements'!$D:$D,"Out") -> 0 | N14: =L14-M14 -> 50 | O14: =IF(N14<=0,"Out",IF(AND(K14<>"",N14<=K14),"Low","In Stock")) -> In Stock | P14: =J14-I14 -> 35
A15: ITM-013 | B15: =A15&" · "&C15 -> ITM-013 · BIG CAP SEAL FOR SLIM GENERIC | C15: BIG CAP SEAL FOR SLIM GENERIC | D15: 10-100-107 | E15: CAPSEALS | F15: 500 PC | G15: SOLD | I15: 100 | J15: 120 | L15: =SUMIFS('Stock Movements'!$E:$E,'Stock Movements'!$C:$C,$B15,'Stock Movements'!$D:$D,"In") -> 100 | M15: =SUMIFS('Stock Movements'!$E:$E,'Stock Movements'!$C:$C,$B15,'Stock Movements'!$D:$D,"Out") -> 100 | N15: =L15-M15 -> 0 | O15: =IF(N15<=0,"Out",IF(AND(K15<>"",N15<=K15),"Low","In Stock")) -> Out | P15: =J15-I15 -> 20
A16: ITM-014 | B16: =A16&" · "&C16 -> ITM-014 · SMALL CAP SEAL FOR SLIM GENERIC | C16: SMALL CAP SEAL FOR SLIM GENERIC | D16: 10-190-107 | E16: CAPSEALS | F16: 1000 PC | I16: 70 | J16: 110 | L16: =SUMIFS('Stock Movements'!$E:$E,'Stock Movements'!$C:$C,$B16,'Stock Movements'!$D:$D,"In") -> 100 | M16: =SUMIFS('Stock Movements'!$E:$E,'Stock Movements'!$C:$C,$B16,'Stock Movements'!$D:$D,"Out") -> 36 | N16: =L16-M16 -> 64 | O16: =IF(N16<=0,"Out",IF(AND(K16<>"",N16<=K16),"Low","In Stock")) -> In Stock | P16: =J16-I16 -> 40
A17: ITM-015 | B17: =A17&" · "&C17 -> ITM-015 · FAUCET SEAL FOR SLIM GENERIC | C17: FAUCET SEAL FOR SLIM GENERIC | D17: 10-140-107 | E17: CAPSEALS | F17: 1000 PC | G17: SOLD | I17: 100 | J17: 170 | L17: =SUMIFS('Stock Movements'!$E:$E,'Stock Movements'!$C:$C,$B17,'Stock Movements'!$D:$D,"In") -> 100 | M17: =SUMIFS('Stock Movements'!$E:$E,'Stock Movements'!$C:$C,$B17,'Stock Movements'!$D:$D,"Out") -> 100 | N17: =L17-M17 -> 0 | O17: =IF(N17<=0,"Out",IF(AND(K17<>"",N17<=K17),"Low","In Stock")) -> Out | P17: =J17-I17 -> 70
A18: ITM-016 | B18: =A18&" · "&C18 -> ITM-016 · FAUCET SEAL FOR SLIM GENERIC | C18: FAUCET SEAL FOR SLIM GENERIC | D18: 10-140-107 | E18: CAPSEALS | F18: 1000 PC | G18: NEW BATCH | H18: 5/15/26 | I18: 115 | J18: 180 | L18: =SUMIFS('Stock Movements'!$E:$E,'Stock Movements'!$C:$C,$B18,'Stock Movements'!$D:$D,"In") -> 100 | M18: =SUMIFS('Stock Movements'!$E:$E,'Stock Movements'!$C:$C,$B18,'Stock Movements'!$D:$D,"Out") -> 11 | N18: =L18-M18 -> 89 | O18: =IF(N18<=0,"Out",IF(AND(K18<>"",N18<=K18),"Low","In Stock")) -> In Stock | P18: =J18-I18 -> 65
A19: ITM-017 | B19: =A19&" · "&C19 -> ITM-017 · UMBRELLA SEAL FOR ROUND GENERIC | C19: UMBRELLA SEAL FOR ROUND GENERIC | D19: 10-220-107 | E19: CAPSEALS | F19: 500 PC | I19: 100 | J19: 125 | L19: =SUMIFS('Stock Movements'!$E:$E,'Stock Movements'!$C:$C,$B19,'Stock Movements'!$D:$D,"In") -> 100 | M19: =SUMIFS('Stock Movements'!$E:$E,'Stock Movements'!$C:$C,$B19,'Stock Movements'!$D:$D,"Out") -> 75 | N19: =L19-M19 -> 25 | O19: =IF(N19<=0,"Out",IF(AND(K19<>"",N19<=K19),"Low","In Stock")) -> In Stock | P19: =J19-I19 -> 25
A20: ITM-018 | B20: =A20&" · "&C20 -> ITM-018 · 1 L SOAP SANITIZER | C20: 1 L SOAP SANITIZER | D20: 25-120-101 | E20: SOAP SANITIZER | F20: 1 PC | I20: 49 | J20: 65 | L20: =SUMIFS('Stock Movements'!$E:$E,'Stock Movements'!$C:$C,$B20,'Stock Movements'!$D:$D,"In") -> 80 | M20: =SUMIFS('Stock Movements'!$E:$E,'Stock Movements'!$C:$C,$B20,'Stock Movements'!$D:$D,"Out") -> 35 | N20: =L20-M20 -> 45 | O20: =IF(N20<=0,"Out",IF(AND(K20<>"",N20<=K20),"Low","In Stock")) -> In Stock | P20: =J20-I20 -> 16
A21: ITM-019 | B21: =A21&" · "&C21 -> ITM-019 · SOAP SANITIZER: SOAP WOW-1LITER | C21: SOAP SANITIZER: SOAP WOW-1LITER | D21: 25-420-101 | E21: SOAP SANITIZER | F21: 1 PC | G21: NEW BATCH | H21: 5/15/26 | I21: 63 | J21: 80 | L21: =SUMIFS('Stock Movements'!$E:$E,'Stock Movements'!$C:$C,$B21,'Stock Movements'!$D:$D,"In") -> 32 | M21: =SUMIFS('Stock Movements'!$E:$E,'Stock Movements'!$C:$C,$B21,'Stock Movements'!$D:$D,"Out") -> 0 | N21: =L21-M21 -> 32 | O21: =IF(N21<=0,"Out",IF(AND(K21<>"",N21<=K21),"Low","In Stock")) -> In Stock | P21: =J21-I21 -> 17
A22: ITM-020 | B22: =A22&" · "&C22 -> ITM-020 · AUSTRALIAN SALT | C22: AUSTRALIAN SALT | D22: 19-150-100 | E22: SALT 50KG | F22: 1 SACK | G22: SOLD | I22: 390 | J22: 520 | L22: =SUMIFS('Stock Movements'!$E:$E,'Stock Movements'!$C:$C,$B22,'Stock Movements'!$D:$D,"In") -> 15 | M22: =SUMIFS('Stock Movements'!$E:$E,'Stock Movements'!$C:$C,$B22,'Stock Movements'!$D:$D,"Out") -> 15 | N22: =L22-M22 -> 0 | O22: =IF(N22<=0,"Out",IF(AND(K22<>"",N22<=K22),"Low","In Stock")) -> Out | P22: =J22-I22 -> 130
A23: ITM-021 | B23: =A23&" · "&C23 -> ITM-021 · INDUSTRIAL SALT ART-COURSE | C23: INDUSTRIAL SALT ART-COURSE | E23: SALT 50KG | F23: 1 SACK | I23: 410 | J23: 520 | L23: =SUMIFS('Stock Movements'!$E:$E,'Stock Movements'!$C:$C,$B23,'Stock Movements'!$D:$D,"In") -> 70 | M23: =SUMIFS('Stock Movements'!$E:$E,'Stock Movements'!$C:$C,$B23,'Stock Movements'!$D:$D,"Out") -> 63 | N23: =L23-M23 -> 7 | O23: =IF(N23<=0,"Out",IF(AND(K23<>"",N23<=K23),"Low","In Stock")) -> In Stock | P23: =J23-I23 -> 110
A24: ITM-022 | B24: =A24&" · "&C24 -> ITM-022 · INDUSTRIAL SALT ART-COURSE | C24: INDUSTRIAL SALT ART-COURSE | E24: SALT 50KG | F24: 1 SACK | G24: NEW BATCH | H24: 5/15/26 | I24: 400 | J24: 520 | L24: =SUMIFS('Stock Movements'!$E:$E,'Stock Movements'!$C:$C,$B24,'Stock Movements'!$D:$D,"In") -> 20 | M24: =SUMIFS('Stock Movements'!$E:$E,'Stock Movements'!$C:$C,$B24,'Stock Movements'!$D:$D,"Out") -> 0 | N24: =L24-M24 -> 20 | O24: =IF(N24<=0,"Out",IF(AND(K24<>"",N24<=K24),"Low","In Stock")) -> In Stock | P24: =J24-I24 -> 120
A25: ITM-023 | B25: =A25&" · "&C25 -> ITM-023 · 5M SF 20SL LW ( MONTHLY (2PC) FOR PURIFIED/MINERAL ) | C25: 5M SF 20SL LW ( MONTHLY (2PC) FOR PURIFIED/MINERAL ) | D25: 14-230-116 | E25: FILTERS | F25: 1 PC | I25: 85 | J25: 110 | L25: =SUMIFS('Stock Movements'!$E:$E,'Stock Movements'!$C:$C,$B25,'Stock Movements'!$D:$D,"In") -> 25 | M25: =SUMIFS('Stock Movements'!$E:$E,'Stock Movements'!$C:$C,$B25,'Stock Movements'!$D:$D,"Out") -> 9 | N25: =L25-M25 -> 16 | O25: =IF(N25<=0,"Out",IF(AND(K25<>"",N25<=K25),"Low","In Stock")) -> In Stock | P25: =J25-I25 -> 25
A26: ITM-024 | B26: =A26&" · "&C26 -> ITM-024 · SEDIMENT: LWS 20" SLIM 5-MIC | C26: SEDIMENT: LWS 20" SLIM 5-MIC | D26: 14-230-116 | E26: FILTERS | F26: 1 PC | I26: 75 | J26: 110 | L26: =SUMIFS('Stock Movements'!$E:$E,'Stock Movements'!$C:$C,$B26,'Stock Movements'!$D:$D,"In") -> 10 | M26: =SUMIFS('Stock Movements'!$E:$E,'Stock Movements'!$C:$C,$B26,'Stock Movements'!$D:$D,"Out") -> 0 | N26: =L26-M26 -> 10 | O26: =IF(N26<=0,"Out",IF(AND(K26<>"",N26<=K26),"Low","In Stock")) -> In Stock | P26: =J26-I26 -> 35
A27: ITM-025 | B27: =A27&" · "&C27 -> ITM-025 · 1M SF 20S LW ( QUARTERLY (2PC) FOR PURIFIED/MINERAL ) | C27: 1M SF 20S LW ( QUARTERLY (2PC) FOR PURIFIED/MINERAL ) | D27: 14-230-115 | E27: FILTERS | F27: 1 PC | I27: 95 | J27: 110 | L27: =SUMIFS('Stock Movements'!$E:$E,'Stock Movements'!$C:$C,$B27,'Stock Movements'!$D:$D,"In") -> 25 | M27: =SUMIFS('Stock Movements'!$E:$E,'Stock Movements'!$C:$C,$B27,'Stock Movements'!$D:$D,"Out") -> 13 | N27: =L27-M27 -> 12 | O27: =IF(N27<=0,"Out",IF(AND(K27<>"",N27<=K27),"Low","In Stock")) -> In Stock | P27: =J27-I27 -> 15
A28: ITM-026 | B28: =A28&" · "&C28 -> ITM-026 · SEDIMENT: LWS 20" SLIM 1-MIC | C28: SEDIMENT: LWS 20" SLIM 1-MIC | D28: 14-230-115 | E28: FILTERS | F28: 1 PC | I28: 85 | J28: 110 | L28: =SUMIFS('Stock Movements'!$E:$E,'Stock Movements'!$C:$C,$B28,'Stock Movements'!$D:$D,"In") -> 5 | M28: =SUMIFS('Stock Movements'!$E:$E,'Stock Movements'!$C:$C,$B28,'Stock Movements'!$D:$D,"Out") -> 0 | N28: =L28-M28 -> 5 | O28: =IF(N28<=0,"Out",IF(AND(K28<>"",N28<=K28),"Low","In Stock")) -> In Stock | P28: =J28-I28 -> 25
A29: ITM-027 | B29: =A29&" · "&C29 -> ITM-027 · 1M SF 10SL LW ( QUARTERLY (1PC) FOR ALKALINE ) (SEDIMENT: LWS 10" SLIM 1-MIC) | C29: 1M SF 10SL LW ( QUARTERLY (1PC) FOR ALKALINE ) (SEDIMENT: LWS 10" SLIM 1-MIC) | D29: 14-230-114 | E29: FILTERS | F29: 1 PC | I29: 61 | J29: 90 | L29: =SUMIFS('Stock Movements'!$E:$E,'Stock Movements'!$C:$C,$B29,'Stock Movements'!$D:$D,"In") -> 15 | M29: =SUMIFS('Stock Movements'!$E:$E,'Stock Movements'!$C:$C,$B29,'Stock Movements'!$D:$D,"Out") -> 6 | N29: =L29-M29 -> 9 | O29: =IF(N29<=0,"Out",IF(AND(K29<>"",N29<=K29),"Low","In Stock")) -> In Stock | P29: =J29-I29 -> 29
A30: ITM-028 | B30: =A30&" · "&C30 -> ITM-028 · HYDROSEP CTO 20SL ( QUARTERLY (2PC) FOR PURIFIED/MINERAL ) | C30: HYDROSEP CTO 20SL ( QUARTERLY (2PC) FOR PURIFIED/MINERAL ) | D30: 14-130-103 | E30: FILTERS | F30: 1 PC | I30: 620 | J30: 750 | L30: =SUMIFS('Stock Movements'!$E:$E,'Stock Movements'!$C:$C,$B30,'Stock Movements'!$D:$D,"In") -> 25 | M30: =SUMIFS('Stock Movements'!$E:$E,'Stock Movements'!$C:$C,$B30,'Stock Movements'!$D:$D,"Out") -> 20 | N30: =L30-M30 -> 5 | O30: =IF(N30<=0,"Out",IF(AND(K30<>"",N30<=K30),"Low","In Stock")) -> In Stock | P30: =J30-I30 -> 130
A31: ITM-029 | B31: =A31&" · "&C31 -> ITM-029 · HYDROSEP CTO 10SL ( QUARTERLY (1PC) FOR ALKALINE ) | C31: HYDROSEP CTO 10SL ( QUARTERLY (1PC) FOR ALKALINE ) | D31: 14-130-101 | E31: FILTERS | F31: 1 PC | I31: 350 | J31: 400 | L31: =SUMIFS('Stock Movements'!$E:$E,'Stock Movements'!$C:$C,$B31,'Stock Movements'!$D:$D,"In") -> 10 | M31: =SUMIFS('Stock Movements'!$E:$E,'Stock Movements'!$C:$C,$B31,'Stock Movements'!$D:$D,"Out") -> 6 | N31: =L31-M31 -> 4 | O31: =IF(N31<=0,"Out",IF(AND(K31<>"",N31<=K31),"Low","In Stock")) -> In Stock | P31: =J31-I31 -> 50
A32: ITM-030 | B32: =A32&" · "&C32 -> ITM-030 · CERAMIC FILTER 10SL ( QUARTERLY (1PC) FOR ALKALINE ) | C32: CERAMIC FILTER 10SL ( QUARTERLY (1PC) FOR ALKALINE ) | D32: 14-150-100 | E32: FILTERS | F32: 1 PC | I32: 500 | J32: 770 | L32: =SUMIFS('Stock Movements'!$E:$E,'Stock Movements'!$C:$C,$B32,'Stock Movements'!$D:$D,"In") -> 10 | M32: =SUMIFS('Stock Movements'!$E:$E,'Stock Movements'!$C:$C,$B32,'Stock Movements'!$D:$D,"Out") -> 3 | N32: =L32-M32 -> 7 | O32: =IF(N32<=0,"Out",IF(AND(K32<>"",N32<=K32),"Low","In Stock")) -> In Stock | P32: =J32-I32 -> 270
A33: ITM-031 | B33: =A33&" · "&C33 -> ITM-031 · BIO FILTER 10SL ( QUARTERLY (1PC) FOR ALKALINE ) | C33: BIO FILTER 10SL ( QUARTERLY (1PC) FOR ALKALINE ) | D33: 14-110-100 | E33: FILTERS | F33: 1 PC | I33: 1018 | J33: 1550 | L33: =SUMIFS('Stock Movements'!$E:$E,'Stock Movements'!$C:$C,$B33,'Stock Movements'!$D:$D,"In") -> 10 | M33: =SUMIFS('Stock Movements'!$E:$E,'Stock Movements'!$C:$C,$B33,'Stock Movements'!$D:$D,"Out") -> 2 | N33: =L33-M33 -> 8 | O33: =IF(N33<=0,"Out",IF(AND(K33<>"",N33<=K33),"Low","In Stock")) -> In Stock | P33: =J33-I33 -> 532
A34: ITM-032 | B34: =A34&" · "&C34 -> ITM-032 · WOW 20" SLIM 5-MIC | C34: WOW 20" SLIM 5-MIC | E34: FILTERS | F34: 1 PC | I34: 70 | J34: 90 | L34: =SUMIFS('Stock Movements'!$E:$E,'Stock Movements'!$C:$C,$B34,'Stock Movements'!$D:$D,"In") -> 25 | M34: =SUMIFS('Stock Movements'!$E:$E,'Stock Movements'!$C:$C,$B34,'Stock Movements'!$D:$D,"Out") -> 10 | N34: =L34-M34 -> 15 | O34: =IF(N34<=0,"Out",IF(AND(K34<>"",N34<=K34),"Low","In Stock")) -> In Stock | P34: =J34-I34 -> 20
A35: ITM-033 | B35: =A35&" · "&C35 -> ITM-033 · WOW 20" SLIM 1-MIC | C35: WOW 20" SLIM 1-MIC | E35: FILTERS | F35: 1 PC | I35: 70 | J35: 90 | L35: =SUMIFS('Stock Movements'!$E:$E,'Stock Movements'!$C:$C,$B35,'Stock Movements'!$D:$D,"In") -> 25 | M35: =SUMIFS('Stock Movements'!$E:$E,'Stock Movements'!$C:$C,$B35,'Stock Movements'!$D:$D,"Out") -> 10 | N35: =L35-M35 -> 15 | O35: =IF(N35<=0,"Out",IF(AND(K35<>"",N35<=K35),"Low","In Stock")) -> In Stock | P35: =J35-I35 -> 20
A36: ITM-034 | B36: =A36&" · "&C36 -> ITM-034 · WOW 10" SLIM 1-MIC | C36: WOW 10" SLIM 1-MIC | E36: FILTERS | F36: 1 PC | I36: 48 | J36: 50 | L36: =SUMIFS('Stock Movements'!$E:$E,'Stock Movements'!$C:$C,$B36,'Stock Movements'!$D:$D,"In") -> 25 | M36: =SUMIFS('Stock Movements'!$E:$E,'Stock Movements'!$C:$C,$B36,'Stock Movements'!$D:$D,"Out") -> 0 | N36: =L36-M36 -> 25 | O36: =IF(N36<=0,"Out",IF(AND(K36<>"",N36<=K36),"Low","In Stock")) -> In Stock | P36: =J36-I36 -> 2
A37: ITM-035 | B37: =A37&" · "&C37 -> ITM-035 · UV LAMPS: UVC-PRO 6 GPM 14W | C37: UV LAMPS: UVC-PRO 6 GPM 14W | D37: 27-130-102 | E37: FILTERS | F37: 1 PC | I37: 1000 | L37: =SUMIFS('Stock Movements'!$E:$E,'Stock Movements'!$C:$C,$B37,'Stock Movements'!$D:$D,"In") -> 4 | M37: =SUMIFS('Stock Movements'!$E:$E,'Stock Movements'!$C:$C,$B37,'Stock Movements'!$D:$D,"Out") -> 0 | N37: =L37-M37 -> 4 | O37: =IF(N37<=0,"Out",IF(AND(K37<>"",N37<=K37),"Low","In Stock")) -> In Stock | P37: =J37-I37 -> -1000
A38: ITM-036 | B38: =A38&" · "&C38 -> ITM-036 · 350 ML PET BOTTLE (WITH CAP) | C38: 350 ML PET BOTTLE (WITH CAP) | D38: 10-170-106 | E38: PET BOTTLE | F38: 288 PCS | I38: 634 | J38: 860 | L38: =SUMIFS('Stock Movements'!$E:$E,'Stock Movements'!$C:$C,$B38,'Stock Movements'!$D:$D,"In") -> 32 | M38: =SUMIFS('Stock Movements'!$E:$E,'Stock Movements'!$C:$C,$B38,'Stock Movements'!$D:$D,"Out") -> 23 | N38: =L38-M38 -> 9 | O38: =IF(N38<=0,"Out",IF(AND(K38<>"",N38<=K38),"Low","In Stock")) -> In Stock | P38: =J38-I38 -> 226
A39: ITM-037 | B39: =A39&" · "&C39 -> ITM-037 · 350 ML PET BOTTLE (WITH CAP) | C39: 350 ML PET BOTTLE (WITH CAP) | D39: 10-170-106 | E39: PET BOTTLE | F39: 250 PCS | G39: SOLD | I39: 674 | J39: 900 | L39: =SUMIFS('Stock Movements'!$E:$E,'Stock Movements'!$C:$C,$B39,'Stock Movements'!$D:$D,"In") -> 15 | M39: =SUMIFS('Stock Movements'!$E:$E,'Stock Movements'!$C:$C,$B39,'Stock Movements'!$D:$D,"Out") -> 15 | N39: =L39-M39 -> 0 | O39: =IF(N39<=0,"Out",IF(AND(K39<>"",N39<=K39),"Low","In Stock")) -> Out | P39: =J39-I39 -> 226
A40: ITM-038 | B40: =A40&" · "&C40 -> ITM-038 · 500 ML PET BOTTLE (WITH CAP) | C40: 500 ML PET BOTTLE (WITH CAP) | D40: 10-170-115 | E40: PET BOTTLE | F40: 220 PCS | I40: 559 | J40: 760 | L40: =SUMIFS('Stock Movements'!$E:$E,'Stock Movements'!$C:$C,$B40,'Stock Movements'!$D:$D,"In") -> 10 | M40: =SUMIFS('Stock Movements'!$E:$E,'Stock Movements'!$C:$C,$B40,'Stock Movements'!$D:$D,"Out") -> 4 | N40: =L40-M40 -> 6 | O40: =IF(N40<=0,"Out",IF(AND(K40<>"",N40<=K40),"Low","In Stock")) -> In Stock | P40: =J40-I40 -> 201
...

Sheet Stock Movements
A1: STOCK MOVEMENTS (single ledger - replaces the old manual +N chains)
A2: Move ID | B2: Date | C2: Item Label | D2: Direction | E2: Quantity | F2: Buyer | G2: Source | H2: Reference | I2: Note
A3: MV-0001 | B3: 2026-05-16 | C3: ='Item Catalog'!$B$3 -> ITM-001 · 5 GAL SLIM CONTAINER W/ CAP BLUE | D3: In | E3: 526 | G3: Historical Import | H3: Restock (pre-migration cumulative) | I3: Historical cumulative total migrated from STOCK_REPORT.xlsx snapshot
A4: MV-0002 | B4: 2026-05-16 | C4: ='Item Catalog'!$B$3 -> ITM-001 · 5 GAL SLIM CONTAINER W/ CAP BLUE | D4: Out | E4: 87 | F4: A&G (LW-BAAO) | G4: Historical Import | H4: Wholesale/retail dispatch (pre-migration cumulative) | I4: Historical cumulative total migrated from STOCK_REPORT.xlsx snapshot
A5: MV-0003 | B5: 2026-05-16 | C5: ='Item Catalog'!$B$3 -> ITM-001 · 5 GAL SLIM CONTAINER W/ CAP BLUE | D5: Out | E5: 55 | F5: ALKAVIVA (BAAO) | G5: Historical Import | H5: Wholesale/retail dispatch (pre-migration cumulative) | I5: Historical cumulative total migrated from STOCK_REPORT.xlsx snapshot
A6: MV-0004 | B6: 2026-05-16 | C6: ='Item Catalog'!$B$3 -> ITM-001 · 5 GAL SLIM CONTAINER W/ CAP BLUE | D6: Out | E6: 100 | F6: CITY WATER (LW-TAPAYAS) | G6: Historical Import | H6: Wholesale/retail dispatch (pre-migration cumulative) | I6: Historical cumulative total migrated from STOCK_REPORT.xlsx snapshot
A7: MV-0005 | B7: 2026-05-16 | C7: ='Item Catalog'!$B$3 -> ITM-001 · 5 GAL SLIM CONTAINER W/ CAP BLUE | D7: Out | E7: 60 | F7: PURE DROP | G7: Historical Import | H7: Wholesale/retail dispatch (pre-migration cumulative) | I7: Historical cumulative total migrated from STOCK_REPORT.xlsx snapshot
A8: MV-0006 | B8: 2026-05-16 | C8: ='Item Catalog'!$B$3 -> ITM-001 · 5 GAL SLIM CONTAINER W/ CAP BLUE | D8: Out | E8: 19 | F8: LW (BATO) | G8: Historical Import | H8: Wholesale/retail dispatch (pre-migration cumulative) | I8: Historical cumulative total migrated from STOCK_REPORT.xlsx snapshot
A9: MV-0007 | B9: 2026-05-16 | C9: ='Item Catalog'!$B$3 -> ITM-001 · 5 GAL SLIM CONTAINER W/ CAP BLUE | D9: Out | E9: 58 | F9: SARALEX | G9: Historical Import | H9: Wholesale/retail dispatch (pre-migration cumulative) | I9: Historical cumulative total migrated from STOCK_REPORT.xlsx snapshot
A10: MV-0008 | B10: 2026-05-16 | C10: ='Item Catalog'!$B$3 -> ITM-001 · 5 GAL SLIM CONTAINER W/ CAP BLUE | D10: Out | E10: 59 | F10: CRYSTAL REF. STATION | G10: Historical Import | H10: Wholesale/retail dispatch (pre-migration cumulative) | I10: Historical cumulative total migrated from STOCK_REPORT.xlsx snapshot
A11: MV-0009 | B11: 2026-05-16 | C11: ='Item Catalog'!$B$3 -> ITM-001 · 5 GAL SLIM CONTAINER W/ CAP BLUE | D11: Out | E11: 28 | F11: WATER MARKET (BAAO) | G11: Historical Import | H11: Wholesale/retail dispatch (pre-migration cumulative) | I11: Historical cumulative total migrated from STOCK_REPORT.xlsx snapshot
A12: MV-0010 | B12: 2026-05-16 | C12: ='Item Catalog'!$B$3 -> ITM-001 · 5 GAL SLIM CONTAINER W/ CAP BLUE | D12: Out | E12: 25 | F12: AQUARES | G12: Historical Import | H12: Wholesale/retail dispatch (pre-migration cumulative) | I12: Historical cumulative total migrated from STOCK_REPORT.xlsx snapshot
A13: MV-0011 | B13: 2026-05-16 | C13: ='Item Catalog'!$B$3 -> ITM-001 · 5 GAL SLIM CONTAINER W/ CAP BLUE | D13: Out | E13: 35 | F13: ALKAVIVA (BARAS) | G13: Historical Import | H13: Wholesale/retail dispatch (pre-migration cumulative) | I13: Historical cumulative total migrated from STOCK_REPORT.xlsx snapshot
A14: MV-0012 | B14: 2026-05-16 | C14: ='Item Catalog'!$B$4 -> ITM-002 · 5 GAL SLIM CONTAINER W/ CAP BLUE-WOW | D14: In | E14: 200 | G14: Historical Import | H14: Restock (pre-migration cumulative) | I14: Historical cumulative total migrated from STOCK_REPORT.xlsx snapshot
A15: MV-0013 | B15: 2026-05-16 | C15: ='Item Catalog'!$B$4 -> ITM-002 · 5 GAL SLIM CONTAINER W/ CAP BLUE-WOW | D15: Out | E15: 18 | F15: A&G (LW-BAAO) | G15: Historical Import | H15: Wholesale/retail dispatch (pre-migration cumulative) | I15: Historical cumulative total migrated from STOCK_REPORT.xlsx snapshot
A16: MV-0014 | B16: 2026-05-16 | C16: ='Item Catalog'!$B$4 -> ITM-002 · 5 GAL SLIM CONTAINER W/ CAP BLUE-WOW | D16: Out | E16: 5 | F16: ALKAVIVA (BAAO) | G16: Historical Import | H16: Wholesale/retail dispatch (pre-migration cumulative) | I16: Historical cumulative total migrated from STOCK_REPORT.xlsx snapshot
A17: MV-0015 | B17: 2026-05-16 | C17: ='Item Catalog'!$B$4 -> ITM-002 · 5 GAL SLIM CONTAINER W/ CAP BLUE-WOW | D17: Out | E17: 10 | F17: PURE DROP | G17: Historical Import | H17: Wholesale/retail dispatch (pre-migration cumulative) | I17: Historical cumulative total migrated from STOCK_REPORT.xlsx snapshot
A18: MV-0016 | B18: 2026-05-16 | C18: ='Item Catalog'!$B$4 -> ITM-002 · 5 GAL SLIM CONTAINER W/ CAP BLUE-WOW | D18: Out | E18: 20 | F18: CRYSTAL REF. STATION | G18: Historical Import | H18: Wholesale/retail dispatch (pre-migration cumulative) | I18: Historical cumulative total migrated from STOCK_REPORT.xlsx snapshot
A19: MV-0017 | B19: 2026-05-16 | C19: ='Item Catalog'!$B$5 -> ITM-003 · 5 GAL SLIM CONTAINER W/ CAP GREEN | D19: In | E19: 350 | G19: Historical Import | H19: Restock (pre-migration cumulative) | I19: Historical cumulative total migrated from STOCK_REPORT.xlsx snapshot
A20: MV-0018 | B20: 2026-05-16 | C20: ='Item Catalog'!$B$5 -> ITM-003 · 5 GAL SLIM CONTAINER W/ CAP GREEN | D20: Out | E20: 81 | F20: A&G (LW-BAAO) | G20: Historical Import | H20: Wholesale/retail dispatch (pre-migration cumulative) | I20: Historical cumulative total migrated from STOCK_REPORT.xlsx snapshot
A21: MV-0019 | B21: 2026-05-16 | C21: ='Item Catalog'!$B$5 -> ITM-003 · 5 GAL SLIM CONTAINER W/ CAP GREEN | D21: Out | E21: 8 | F21: CRYSTAL REF. STATION | G21: Historical Import | H21: Wholesale/retail dispatch (pre-migration cumulative) | I21: Historical cumulative total migrated from STOCK_REPORT.xlsx snapshot
A22: MV-0020 | B22: 2026-05-16 | C22: ='Item Catalog'!$B$5 -> ITM-003 · 5 GAL SLIM CONTAINER W/ CAP GREEN | D22: Out | E22: 35 | F22: ALKAVIVA (BARAS) | G22: Historical Import | H22: Wholesale/retail dispatch (pre-migration cumulative) | I22: Historical cumulative total migrated from STOCK_REPORT.xlsx snapshot
A23: MV-0021 | B23: 2026-05-16 | C23: ='Item Catalog'!$B$5 -> ITM-003 · 5 GAL SLIM CONTAINER W/ CAP GREEN | D23: Out | E23: 91 | F23: WATER MARKET (BAAO) | G23: Historical Import | H23: Wholesale/retail dispatch (pre-migration cumulative) | I23: Historical cumulative total migrated from STOCK_REPORT.xlsx snapshot
A24: MV-0022 | B24: 2026-05-16 | C24: ='Item Catalog'!$B$5 -> ITM-003 · 5 GAL SLIM CONTAINER W/ CAP GREEN | D24: Out | E24: 5 | F24: AQUARES | G24: Historical Import | H24: Wholesale/retail dispatch (pre-migration cumulative) | I24: Historical cumulative total migrated from STOCK_REPORT.xlsx snapshot
A25: MV-0023 | B25: 2026-05-16 | C25: ='Item Catalog'!$B$6 -> ITM-004 · 5 GAL SLIM CONTAINER W/ CAP YELLOW | D25: In | E25: 350 | G25: Historical Import | H25: Restock (pre-migration cumulative) | I25: Historical cumulative total migrated from STOCK_REPORT.xlsx snapshot
A26: MV-0024 | B26: 2026-05-16 | C26: ='Item Catalog'!$B$6 -> ITM-004 · 5 GAL SLIM CONTAINER W/ CAP YELLOW | D26: Out | E26: 38 | F26: A&G (LW-BAAO) | G26: Historical Import | H26: Wholesale/retail dispatch (pre-migration cumulative) | I26: Historical cumulative total migrated from STOCK_REPORT.xlsx snapshot
A27: MV-0025 | B27: 2026-05-16 | C27: ='Item Catalog'!$B$6 -> ITM-004 · 5 GAL SLIM CONTAINER W/ CAP YELLOW | D27: Out | E27: 10 | F27: CRYSTAL REF. STATION | G27: Historical Import | H27: Wholesale/retail dispatch (pre-migration cumulative) | I27: Historical cumulative total migrated from STOCK_REPORT.xlsx snapshot
A28: MV-0026 | B28: 2026-05-16 | C28: ='Item Catalog'!$B$6 -> ITM-004 · 5 GAL SLIM CONTAINER W/ CAP YELLOW | D28: Out | E28: 10 | F28: ALKAVIVA (BARAS) | G28: Historical Import | H28: Wholesale/retail dispatch (pre-migration cumulative) | I28: Historical cumulative total migrated from STOCK_REPORT.xlsx snapshot
A29: MV-0027 | B29: 2026-05-16 | C29: ='Item Catalog'!$B$7 -> ITM-005 · 5 GAL (PET) ROUND CONTAINER BLUE W/ CAP (CLASS A) | D29: In | E29: 200 | G29: Historical Import | H29: Restock (pre-migration cumulative) | I29: Historical cumulative total migrated from STOCK_REPORT.xlsx snapshot
A30: MV-0028 | B30: 2026-05-16 | C30: ='Item Catalog'!$B$7 -> ITM-005 · 5 GAL (PET) ROUND CONTAINER BLUE W/ CAP (CLASS A) | D30: Out | E30: 35 | F30: A&G (LW-BAAO) | G30: Historical Import | H30: Wholesale/retail dispatch (pre-migration cumulative) | I30: Historical cumulative total migrated from STOCK_REPORT.xlsx snapshot
A31: MV-0029 | B31: 2026-05-16 | C31: ='Item Catalog'!$B$7 -> ITM-005 · 5 GAL (PET) ROUND CONTAINER BLUE W/ CAP (CLASS A) | D31: Out | E31: 5 | F31: ALKAVIVA (BAAO) | G31: Historical Import | H31: Wholesale/retail dispatch (pre-migration cumulative) | I31: Historical cumulative total migrated from STOCK_REPORT.xlsx snapshot
A32: MV-0030 | B32: 2026-05-16 | C32: ='Item Catalog'!$B$7 -> ITM-005 · 5 GAL (PET) ROUND CONTAINER BLUE W/ CAP (CLASS A) | D32: Out | E32: 15 | F32: CITY WATER (LW-TAPAYAS) | G32: Historical Import | H32: Wholesale/retail dispatch (pre-migration cumulative) | I32: Historical cumulative total migrated from STOCK_REPORT.xlsx snapshot
A33: MV-0031 | B33: 2026-05-16 | C33: ='Item Catalog'!$B$7 -> ITM-005 · 5 GAL (PET) ROUND CONTAINER BLUE W/ CAP (CLASS A) | D33: Out | E33: 60 | F33: PURE DROP | G33: Historical Import | H33: Wholesale/retail dispatch (pre-migration cumulative) | I33: Historical cumulative total migrated from STOCK_REPORT.xlsx snapshot
A34: MV-0032 | B34: 2026-05-16 | C34: ='Item Catalog'!$B$7 -> ITM-005 · 5 GAL (PET) ROUND CONTAINER BLUE W/ CAP (CLASS A) | D34: Out | E34: 9 | F34: LW (BATO) | G34: Historical Import | H34: Wholesale/retail dispatch (pre-migration cumulative) | I34: Historical cumulative total migrated from STOCK_REPORT.xlsx snapshot
A35: MV-0033 | B35: 2026-05-16 | C35: ='Item Catalog'!$B$7 -> ITM-005 · 5 GAL (PET) ROUND CONTAINER BLUE W/ CAP (CLASS A) | D35: Out | E35: 6 | F35: SARALEX | G35: Historical Import | H35: Wholesale/retail dispatch (pre-migration cumulative) | I35: Historical cumulative total migrated from STOCK_REPORT.xlsx snapshot
A36: MV-0034 | B36: 2026-05-16 | C36: ='Item Catalog'!$B$7 -> ITM-005 · 5 GAL (PET) ROUND CONTAINER BLUE W/ CAP (CLASS A) | D36: Out | E36: 13 | F36: CRYSTAL REF. STATION | G36: Historical Import | H36: Wholesale/retail dispatch (pre-migration cumulative) | I36: Historical cumulative total migrated from STOCK_REPORT.xlsx snapshot
A37: MV-0035 | B37: 2026-05-16 | C37: ='Item Catalog'!$B$7 -> ITM-005 · 5 GAL (PET) ROUND CONTAINER BLUE W/ CAP (CLASS A) | D37: Out | E37: 9 | F37: WATER MARKET (BAAO) | G37: Historical Import | H37: Wholesale/retail dispatch (pre-migration cumulative) | I37: Historical cumulative total migrated from STOCK_REPORT.xlsx snapshot
A38: MV-0036 | B38: 2026-05-16 | C38: ='Item Catalog'!$B$7 -> ITM-005 · 5 GAL (PET) ROUND CONTAINER BLUE W/ CAP (CLASS A) | D38: Out | E38: 25 | F38: AQUARES | G38: Historical Import | H38: Wholesale/retail dispatch (pre-migration cumulative) | I38: Historical cumulative total migrated from STOCK_REPORT.xlsx snapshot
A39: MV-0037 | B39: 2026-05-16 | C39: ='Item Catalog'!$B$7 -> ITM-005 · 5 GAL (PET) ROUND CONTAINER BLUE W/ CAP (CLASS A) | D39: Out | E39: 22 | F39: ALKAVIVA (BARAS) | G39: Historical Import | H39: Wholesale/retail dispatch (pre-migration cumulative) | I39: Historical cumulative total migrated from STOCK_REPORT.xlsx snapshot
A40: MV-0038 | B40: 2026-05-16 | C40: ='Item Catalog'!$B$8 -> ITM-006 · 5 GAL (PET) ROUND CONTAINER BLUE W/ CAP (CLASS A) | D40: In | E40: 100 | G40: Historical Import | H40: Restock (pre-migration cumulative) | I40: Historical cumulative total migrated from STOCK_REPORT.xlsx snapshot
...

Sheet Buyer Summary
A1: BUYER SUMMARY (auto-computed pivot - do not type into buyer columns)
A2: Item Label | B2: Item Name | C2: A&G (LW-BAAO) | D2: ALKAVIVA (BAAO) | E2: OTHERS (CUSTOMER) | F2: CRISPY KING | G2: CITY WATER (LW-TAPAYAS) | H2: PURE DROP | I2: LW (SORSOGON) | J2: LW (BATO) | K2: SARALEX | L2: CRYSTAL REF. STATION | M2: WATER MARKET (BAAO) | N2: AQUARES | O2: LANON W.R.S. | P2: W.L.D. REF. STN (BATO) | Q2: ALKAVIVA (BARAS) | R2: SHAUNTI REF. STN. | S2: Row Total | T2: Check vs Qty Stock Out
A3: ='Item Catalog'!$B$3 -> ITM-001 · 5 GAL SLIM CONTAINER W/ CAP BLUE | B3: ='Item Catalog'!$C$3 -> 5 GAL SLIM CONTAINER W/ CAP BLUE | C3: =SUMIFS('Stock Movements'!$E:$E,'Stock Movements'!$C:$C,$A3,'Stock Movements'!$F:$F,C$2,'Stock Movements'!$D:$D,"Out") -> 87 | D3: =SUMIFS('Stock Movements'!$E:$E,'Stock Movements'!$C:$C,$A3,'Stock Movements'!$F:$F,D$2,'Stock Movements'!$D:$D,"Out") -> 55 | E3: =SUMIFS('Stock Movements'!$E:$E,'Stock Movements'!$C:$C,$A3,'Stock Movements'!$F:$F,E$2,'Stock Movements'!$D:$D,"Out") -> 0 | F3: =SUMIFS('Stock Movements'!$E:$E,'Stock Movements'!$C:$C,$A3,'Stock Movements'!$F:$F,F$2,'Stock Movements'!$D:$D,"Out") -> 0 | G3: =SUMIFS('Stock Movements'!$E:$E,'Stock Movements'!$C:$C,$A3,'Stock Movements'!$F:$F,G$2,'Stock Movements'!$D:$D,"Out") -> 100 | H3: =SUMIFS('Stock Movements'!$E:$E,'Stock Movements'!$C:$C,$A3,'Stock Movements'!$F:$F,H$2,'Stock Movements'!$D:$D,"Out") -> 60 | I3: =SUMIFS('Stock Movements'!$E:$E,'Stock Movements'!$C:$C,$A3,'Stock Movements'!$F:$F,I$2,'Stock Movements'!$D:$D,"Out") -> 0 | J3: =SUMIFS('Stock Movements'!$E:$E,'Stock Movements'!$C:$C,$A3,'Stock Movements'!$F:$F,J$2,'Stock Movements'!$D:$D,"Out") -> 19 | ... R3: =SUMIFS('Stock Movements'!$E:$E,'Stock Movements'!$C:$C,$A3,'Stock Movements'!$F:$F,R$2,'Stock Movements'!$D:$D,"Out") -> 0 | S3: =SUM(C3:R3) -> 526 | T3: =S3-'Item Catalog'!$M$3 -> 0
A4: ='Item Catalog'!$B$4 -> ITM-002 · 5 GAL SLIM CONTAINER W/ CAP BLUE-WOW | B4: ='Item Catalog'!$C$4 -> 5 GAL SLIM CONTAINER W/ CAP BLUE-WOW | C4: =SUMIFS('Stock Movements'!$E:$E,'Stock Movements'!$C:$C,$A4,'Stock Movements'!$F:$F,C$2,'Stock Movements'!$D:$D,"Out") -> 18 | D4: =SUMIFS('Stock Movements'!$E:$E,'Stock Movements'!$C:$C,$A4,'Stock Movements'!$F:$F,D$2,'Stock Movements'!$D:$D,"Out") -> 5 | E4: =SUMIFS('Stock Movements'!$E:$E,'Stock Movements'!$C:$C,$A4,'Stock Movements'!$F:$F,E$2,'Stock Movements'!$D:$D,"Out") -> 0 | F4: =SUMIFS('Stock Movements'!$E:$E,'Stock Movements'!$C:$C,$A4,'Stock Movements'!$F:$F,F$2,'Stock Movements'!$D:$D,"Out") -> 0 | G4: =SUMIFS('Stock Movements'!$E:$E,'Stock Movements'!$C:$C,$A4,'Stock Movements'!$F:$F,G$2,'Stock Movements'!$D:$D,"Out") -> 0 | H4: =SUMIFS('Stock Movements'!$E:$E,'Stock Movements'!$C:$C,$A4,'Stock Movements'!$F:$F,H$2,'Stock Movements'!$D:$D,"Out") -> 10 | I4: =SUMIFS('Stock Movements'!$E:$E,'Stock Movements'!$C:$C,$A4,'Stock Movements'!$F:$F,I$2,'Stock Movements'!$D:$D,"Out") -> 0 | J4: =SUMIFS('Stock Movements'!$E:$E,'Stock Movements'!$C:$C,$A4,'Stock Movements'!$F:$F,J$2,'Stock Movements'!$D:$D,"Out") -> 0 | ... R4: =SUMIFS('Stock Movements'!$E:$E,'Stock Movements'!$C:$C,$A4,'Stock Movements'!$F:$F,R$2,'Stock Movements'!$D:$D,"Out") -> 0 | S4: =SUM(C4:R4) -> 53 | T4: =S4-'Item Catalog'!$M$4 -> 0
A5: ='Item Catalog'!$B$5 -> ITM-003 · 5 GAL SLIM CONTAINER W/ CAP GREEN | B5: ='Item Catalog'!$C$5 -> 5 GAL SLIM CONTAINER W/ CAP GREEN | C5: =SUMIFS('Stock Movements'!$E:$E,'Stock Movements'!$C:$C,$A5,'Stock Movements'!$F:$F,C$2,'Stock Movements'!$D:$D,"Out") -> 81 | D5: =SUMIFS('Stock Movements'!$E:$E,'Stock Movements'!$C:$C,$A5,'Stock Movements'!$F:$F,D$2,'Stock Movements'!$D:$D,"Out") -> 0 | E5: =SUMIFS('Stock Movements'!$E:$E,'Stock Movements'!$C:$C,$A5,'Stock Movements'!$F:$F,E$2,'Stock Movements'!$D:$D,"Out") -> 0 | F5: =SUMIFS('Stock Movements'!$E:$E,'Stock Movements'!$C:$C,$A5,'Stock Movements'!$F:$F,F$2,'Stock Movements'!$D:$D,"Out") -> 0 | G5: =SUMIFS('Stock Movements'!$E:$E,'Stock Movements'!$C:$C,$A5,'Stock Movements'!$F:$F,G$2,'Stock Movements'!$D:$D,"Out") -> 0 | H5: =SUMIFS('Stock Movements'!$E:$E,'Stock Movements'!$C:$C,$A5,'Stock Movements'!$F:$F,H$2,'Stock Movements'!$D:$D,"Out") -> 0 | I5: =SUMIFS('Stock Movements'!$E:$E,'Stock Movements'!$C:$C,$A5,'Stock Movements'!$F:$F,I$2,'Stock Movements'!$D:$D,"Out") -> 0 | J5: =SUMIFS('Stock Movements'!$E:$E,'Stock Movements'!$C:$C,$A5,'Stock Movements'!$F:$F,J$2,'Stock Movements'!$D:$D,"Out") -> 0 | ... R5: =SUMIFS('Stock Movements'!$E:$E,'Stock Movements'!$C:$C,$A5,'Stock Movements'!$F:$F,R$2,'Stock Movements'!$D:$D,"Out") -> 0 | S5: =SUM(C5:R5) -> 220 | T5: =S5-'Item Catalog'!$M$5 -> 0
A6: ='Item Catalog'!$B$6 -> ITM-004 · 5 GAL SLIM CONTAINER W/ CAP YELLOW | B6: ='Item Catalog'!$C$6 -> 5 GAL SLIM CONTAINER W/ CAP YELLOW | C6: =SUMIFS('Stock Movements'!$E:$E,'Stock Movements'!$C:$C,$A6,'Stock Movements'!$F:$F,C$2,'Stock Movements'!$D:$D,"Out") -> 38 | D6: =SUMIFS('Stock Movements'!$E:$E,'Stock Movements'!$C:$C,$A6,'Stock Movements'!$F:$F,D$2,'Stock Movements'!$D:$D,"Out") -> 0 | E6: =SUMIFS('Stock Movements'!$E:$E,'Stock Movements'!$C:$C,$A6,'Stock Movements'!$F:$F,E$2,'Stock Movements'!$D:$D,"Out") -> 0 | F6: =SUMIFS('Stock Movements'!$E:$E,'Stock Movements'!$C:$C,$A6,'Stock Movements'!$F:$F,F$2,'Stock Movements'!$D:$D,"Out") -> 0 | G6: =SUMIFS('Stock Movements'!$E:$E,'Stock Movements'!$C:$C,$A6,'Stock Movements'!$F:$F,G$2,'Stock Movements'!$D:$D,"Out") -> 0 | H6: =SUMIFS('Stock Movements'!$E:$E,'Stock Movements'!$C:$C,$A6,'Stock Movements'!$F:$F,H$2,'Stock Movements'!$D:$D,"Out") -> 0 | I6: =SUMIFS('Stock Movements'!$E:$E,'Stock Movements'!$C:$C,$A6,'Stock Movements'!$F:$F,I$2,'Stock Movements'!$D:$D,"Out") -> 0 | J6: =SUMIFS('Stock Movements'!$E:$E,'Stock Movements'!$C:$C,$A6,'Stock Movements'!$F:$F,J$2,'Stock Movements'!$D:$D,"Out") -> 0 | ... R6: =SUMIFS('Stock Movements'!$E:$E,'Stock Movements'!$C:$C,$A6,'Stock Movements'!$F:$F,R$2,'Stock Movements'!$D:$D,"Out") -> 0 | S6: =SUM(C6:R6) -> 58 | T6: =S6-'Item Catalog'!$M$6 -> 0
A7: ='Item Catalog'!$B$7 -> ITM-005 · 5 GAL (PET) ROUND CONTAINER BLUE W/ CAP (CLASS A) | B7: ='Item Catalog'!$C$7 -> 5 GAL (PET) ROUND CONTAINER BLUE W/ CAP (CLASS A) | C7: =SUMIFS('Stock Movements'!$E:$E,'Stock Movements'!$C:$C,$A7,'Stock Movements'!$F:$F,C$2,'Stock Movements'!$D:$D,"Out") -> 35 | D7: =SUMIFS('Stock Movements'!$E:$E,'Stock Movements'!$C:$C,$A7,'Stock Movements'!$F:$F,D$2,'Stock Movements'!$D:$D,"Out") -> 5 | E7: =SUMIFS('Stock Movements'!$E:$E,'Stock Movements'!$C:$C,$A7,'Stock Movements'!$F:$F,E$2,'Stock Movements'!$D:$D,"Out") -> 0 | F7: =SUMIFS('Stock Movements'!$E:$E,'Stock Movements'!$C:$C,$A7,'Stock Movements'!$F:$F,F$2,'Stock Movements'!$D:$D,"Out") -> 0 | G7: =SUMIFS('Stock Movements'!$E:$E,'Stock Movements'!$C:$C,$A7,'Stock Movements'!$F:$F,G$2,'Stock Movements'!$D:$D,"Out") -> 15 | H7: =SUMIFS('Stock Movements'!$E:$E,'Stock Movements'!$C:$C,$A7,'Stock Movements'!$F:$F,H$2,'Stock Movements'!$D:$D,"Out") -> 60 | I7: =SUMIFS('Stock Movements'!$E:$E,'Stock Movements'!$C:$C,$A7,'Stock Movements'!$F:$F,I$2,'Stock Movements'!$D:$D,"Out") -> 0 | J7: =SUMIFS('Stock Movements'!$E:$E,'Stock Movements'!$C:$C,$A7,'Stock Movements'!$F:$F,J$2,'Stock Movements'!$D:$D,"Out") -> 9 | ... R7: =SUMIFS('Stock Movements'!$E:$E,'Stock Movements'!$C:$C,$A7,'Stock Movements'!$F:$F,R$2,'Stock Movements'!$D:$D,"Out") -> 0 | S7: =SUM(C7:R7) -> 199 | T7: =S7-'Item Catalog'!$M$7 -> 0
A8: ='Item Catalog'!$B$8 -> ITM-006 · 5 GAL (PET) ROUND CONTAINER BLUE W/ CAP (CLASS A) | B8: ='Item Catalog'!$C$8 -> 5 GAL (PET) ROUND CONTAINER BLUE W/ CAP (CLASS A) | C8: =SUMIFS('Stock Movements'!$E:$E,'Stock Movements'!$C:$C,$A8,'Stock Movements'!$F:$F,C$2,'Stock Movements'!$D:$D,"Out") -> 5 | D8: =SUMIFS('Stock Movements'!$E:$E,'Stock Movements'!$C:$C,$A8,'Stock Movements'!$F:$F,D$2,'Stock Movements'!$D:$D,"Out") -> 0 | E8: =SUMIFS('Stock Movements'!$E:$E,'Stock Movements'!$C:$C,$A8,'Stock Movements'!$F:$F,E$2,'Stock Movements'!$D:$D,"Out") -> 0 | F8: =SUMIFS('Stock Movements'!$E:$E,'Stock Movements'!$C:$C,$A8,'Stock Movements'!$F:$F,F$2,'Stock Movements'!$D:$D,"Out") -> 0 | G8: =SUMIFS('Stock Movements'!$E:$E,'Stock Movements'!$C:$C,$A8,'Stock Movements'!$F:$F,G$2,'Stock Movements'!$D:$D,"Out") -> 0 | H8: =SUMIFS('Stock Movements'!$E:$E,'Stock Movements'!$C:$C,$A8,'Stock Movements'!$F:$F,H$2,'Stock Movements'!$D:$D,"Out") -> 0 | I8: =SUMIFS('Stock Movements'!$E:$E,'Stock Movements'!$C:$C,$A8,'Stock Movements'!$F:$F,I$2,'Stock Movements'!$D:$D,"Out") -> 0 | J8: =SUMIFS('Stock Movements'!$E:$E,'Stock Movements'!$C:$C,$A8,'Stock Movements'!$F:$F,J$2,'Stock Movements'!$D:$D,"Out") -> 0 | ... R8: =SUMIFS('Stock Movements'!$E:$E,'Stock Movements'!$C:$C,$A8,'Stock Movements'!$F:$F,R$2,'Stock Movements'!$D:$D,"Out") -> 0 | S8: =SUM(C8:R8) -> 11 | T8: =S8-'Item Catalog'!$M$8 -> 0
A9: ='Item Catalog'!$B$9 -> ITM-007 · BIG CAP SEAL FOR SLIM LW | B9: ='Item Catalog'!$C$9 -> BIG CAP SEAL FOR SLIM LW | C9: =SUMIFS('Stock Movements'!$E:$E,'Stock Movements'!$C:$C,$A9,'Stock Movements'!$F:$F,C$2,'Stock Movements'!$D:$D,"Out") -> 49 | D9: =SUMIFS('Stock Movements'!$E:$E,'Stock Movements'!$C:$C,$A9,'Stock Movements'!$F:$F,D$2,'Stock Movements'!$D:$D,"Out") -> 0 | E9: =SUMIFS('Stock Movements'!$E:$E,'Stock Movements'!$C:$C,$A9,'Stock Movements'!$F:$F,E$2,'Stock Movements'!$D:$D,"Out") -> 0 | F9: =SUMIFS('Stock Movements'!$E:$E,'Stock Movements'!$C:$C,$A9,'Stock Movements'!$F:$F,F$2,'Stock Movements'!$D:$D,"Out") -> 0 | G9: =SUMIFS('Stock Movements'!$E:$E,'Stock Movements'!$C:$C,$A9,'Stock Movements'!$F:$F,G$2,'Stock Movements'!$D:$D,"Out") -> 3 | H9: =SUMIFS('Stock Movements'!$E:$E,'Stock Movements'!$C:$C,$A9,'Stock Movements'!$F:$F,H$2,'Stock Movements'!$D:$D,"Out") -> 0 | I9: =SUMIFS('Stock Movements'!$E:$E,'Stock Movements'!$C:$C,$A9,'Stock Movements'!$F:$F,I$2,'Stock Movements'!$D:$D,"Out") -> 0 | J9: =SUMIFS('Stock Movements'!$E:$E,'Stock Movements'!$C:$C,$A9,'Stock Movements'!$F:$F,J$2,'Stock Movements'!$D:$D,"Out") -> 3 | ... R9: =SUMIFS('Stock Movements'!$E:$E,'Stock Movements'!$C:$C,$A9,'Stock Movements'!$F:$F,R$2,'Stock Movements'!$D:$D,"Out") -> 0 | S9: =SUM(C9:R9) -> 55 | T9: =S9-'Item Catalog'!$M$9 -> 0
A10: ='Item Catalog'!$B$10 -> ITM-008 · SMALL CAP SEAL FOR SLIM LW | B10: ='Item Catalog'!$C$10 -> SMALL CAP SEAL FOR SLIM LW | C10: =SUMIFS('Stock Movements'!$E:$E,'Stock Movements'!$C:$C,$A10,'Stock Movements'!$F:$F,C$2,'Stock Movements'!$D:$D,"Out") -> 19 | D10: =SUMIFS('Stock Movements'!$E:$E,'Stock Movements'!$C:$C,$A10,'Stock Movements'!$F:$F,D$2,'Stock Movements'!$D:$D,"Out") -> 0 | E10: =SUMIFS('Stock Movements'!$E:$E,'Stock Movements'!$C:$C,$A10,'Stock Movements'!$F:$F,E$2,'Stock Movements'!$D:$D,"Out") -> 0 | F10: =SUMIFS('Stock Movements'!$E:$E,'Stock Movements'!$C:$C,$A10,'Stock Movements'!$F:$F,F$2,'Stock Movements'!$D:$D,"Out") -> 0 | G10: =SUMIFS('Stock Movements'!$E:$E,'Stock Movements'!$C:$C,$A10,'Stock Movements'!$F:$F,G$2,'Stock Movements'!$D:$D,"Out") -> 1 | H10: =SUMIFS('Stock Movements'!$E:$E,'Stock Movements'!$C:$C,$A10,'Stock Movements'!$F:$F,H$2,'Stock Movements'!$D:$D,"Out") -> 0 | I10: =SUMIFS('Stock Movements'!$E:$E,'Stock Movements'!$C:$C,$A10,'Stock Movements'!$F:$F,I$2,'Stock Movements'!$D:$D,"Out") -> 0 | J10: =SUMIFS('Stock Movements'!$E:$E,'Stock Movements'!$C:$C,$A10,'Stock Movements'!$F:$F,J$2,'Stock Movements'!$D:$D,"Out") -> 4 | ... R10: =SUMIFS('Stock Movements'!$E:$E,'Stock Movements'!$C:$C,$A10,'Stock Movements'!$F:$F,R$2,'Stock Movements'!$D:$D,"Out") -> 0 | S10: =SUM(C10:R10) -> 24 | T10: =S10-'Item Catalog'!$M$10 -> 0
A11: ='Item Catalog'!$B$11 -> ITM-009 · FAUCET SEAL FOR SLIM LW | B11: ='Item Catalog'!$C$11 -> FAUCET SEAL FOR SLIM LW | C11: =SUMIFS('Stock Movements'!$E:$E,'Stock Movements'!$C:$C,$A11,'Stock Movements'!$F:$F,C$2,'Stock Movements'!$D:$D,"Out") -> 28 | D11: =SUMIFS('Stock Movements'!$E:$E,'Stock Movements'!$C:$C,$A11,'Stock Movements'!$F:$F,D$2,'Stock Movements'!$D:$D,"Out") -> 0 | E11: =SUMIFS('Stock Movements'!$E:$E,'Stock Movements'!$C:$C,$A11,'Stock Movements'!$F:$F,E$2,'Stock Movements'!$D:$D,"Out") -> 0 | F11: =SUMIFS('Stock Movements'!$E:$E,'Stock Movements'!$C:$C,$A11,'Stock Movements'!$F:$F,F$2,'Stock Movements'!$D:$D,"Out") -> 0 | G11: =SUMIFS('Stock Movements'!$E:$E,'Stock Movements'!$C:$C,$A11,'Stock Movements'!$F:$F,G$2,'Stock Movements'!$D:$D,"Out") -> 5 | H11: =SUMIFS('Stock Movements'!$E:$E,'Stock Movements'!$C:$C,$A11,'Stock Movements'!$F:$F,H$2,'Stock Movements'!$D:$D,"Out") -> 0 | I11: =SUMIFS('Stock Movements'!$E:$E,'Stock Movements'!$C:$C,$A11,'Stock Movements'!$F:$F,I$2,'Stock Movements'!$D:$D,"Out") -> 20 | J11: =SUMIFS('Stock Movements'!$E:$E,'Stock Movements'!$C:$C,$A11,'Stock Movements'!$F:$F,J$2,'Stock Movements'!$D:$D,"Out") -> 7 | ... R11: =SUMIFS('Stock Movements'!$E:$E,'Stock Movements'!$C:$C,$A11,'Stock Movements'!$F:$F,R$2,'Stock Movements'!$D:$D,"Out") -> 0 | S11: =SUM(C11:R11) -> 62 | T11: =S11-'Item Catalog'!$M$11 -> 0
A12: ='Item Catalog'!$B$12 -> ITM-010 · FAUCET SEAL FOR SLIM LW (CLASS B) | B12: ='Item Catalog'!$C$12 -> FAUCET SEAL FOR SLIM LW (CLASS B) | C12: =SUMIFS('Stock Movements'!$E:$E,'Stock Movements'!$C:$C,$A12,'Stock Movements'!$F:$F,C$2,'Stock Movements'!$D:$D,"Out") -> 0 | D12: =SUMIFS('Stock Movements'!$E:$E,'Stock Movements'!$C:$C,$A12,'Stock Movements'!$F:$F,D$2,'Stock Movements'!$D:$D,"Out") -> 0 | E12: =SUMIFS('Stock Movements'!$E:$E,'Stock Movements'!$C:$C,$A12,'Stock Movements'!$F:$F,E$2,'Stock Movements'!$D:$D,"Out") -> 0 | F12: =SUMIFS('Stock Movements'!$E:$E,'Stock Movements'!$C:$C,$A12,'Stock Movements'!$F:$F,F$2,'Stock Movements'!$D:$D,"Out") -> 0 | G12: =SUMIFS('Stock Movements'!$E:$E,'Stock Movements'!$C:$C,$A12,'Stock Movements'!$F:$F,G$2,'Stock Movements'!$D:$D,"Out") -> 0 | H12: =SUMIFS('Stock Movements'!$E:$E,'Stock Movements'!$C:$C,$A12,'Stock Movements'!$F:$F,H$2,'Stock Movements'!$D:$D,"Out") -> 0 | I12: =SUMIFS('Stock Movements'!$E:$E,'Stock Movements'!$C:$C,$A12,'Stock Movements'!$F:$F,I$2,'Stock Movements'!$D:$D,"Out") -> 0 | J12: =SUMIFS('Stock Movements'!$E:$E,'Stock Movements'!$C:$C,$A12,'Stock Movements'!$F:$F,J$2,'Stock Movements'!$D:$D,"Out") -> 0 | ... R12: =SUMIFS('Stock Movements'!$E:$E,'Stock Movements'!$C:$C,$A12,'Stock Movements'!$F:$F,R$2,'Stock Movements'!$D:$D,"Out") -> 0 | S12: =SUM(C12:R12) -> 0 | T12: =S12-'Item Catalog'!$M$12 -> 0
A13: ='Item Catalog'!$B$13 -> ITM-011 · UMBRELLA SEAL FOR ROUND LW | B13: ='Item Catalog'!$C$13 -> UMBRELLA SEAL FOR ROUND LW | C13: =SUMIFS('Stock Movements'!$E:$E,'Stock Movements'!$C:$C,$A13,'Stock Movements'!$F:$F,C$2,'Stock Movements'!$D:$D,"Out") -> 8 | D13: =SUMIFS('Stock Movements'!$E:$E,'Stock Movements'!$C:$C,$A13,'Stock Movements'!$F:$F,D$2,'Stock Movements'!$D:$D,"Out") -> 0 | E13: =SUMIFS('Stock Movements'!$E:$E,'Stock Movements'!$C:$C,$A13,'Stock Movements'!$F:$F,E$2,'Stock Movements'!$D:$D,"Out") -> 0 | F13: =SUMIFS('Stock Movements'!$E:$E,'Stock Movements'!$C:$C,$A13,'Stock Movements'!$F:$F,F$2,'Stock Movements'!$D:$D,"Out") -> 0 | G13: =SUMIFS('Stock Movements'!$E:$E,'Stock Movements'!$C:$C,$A13,'Stock Movements'!$F:$F,G$2,'Stock Movements'!$D:$D,"Out") -> 2 | H13: =SUMIFS('Stock Movements'!$E:$E,'Stock Movements'!$C:$C,$A13,'Stock Movements'!$F:$F,H$2,'Stock Movements'!$D:$D,"Out") -> 0 | I13: =SUMIFS('Stock Movements'!$E:$E,'Stock Movements'!$C:$C,$A13,'Stock Movements'!$F:$F,I$2,'Stock Movements'!$D:$D,"Out") -> 20 | J13: =SUMIFS('Stock Movements'!$E:$E,'Stock Movements'!$C:$C,$A13,'Stock Movements'!$F:$F,J$2,'Stock Movements'!$D:$D,"Out") -> 2 | ... R13: =SUMIFS('Stock Movements'!$E:$E,'Stock Movements'!$C:$C,$A13,'Stock Movements'!$F:$F,R$2,'Stock Movements'!$D:$D,"Out") -> 0 | S13: =SUM(C13:R13) -> 33 | T13: =S13-'Item Catalog'!$M$13 -> 0
A14: ='Item Catalog'!$B$14 -> ITM-012 · UMBRELLA SEAL FOR ROUND LW (CLASS B) | B14: ='Item Catalog'!$C$14 -> UMBRELLA SEAL FOR ROUND LW (CLASS B) | C14: =SUMIFS('Stock Movements'!$E:$E,'Stock Movements'!$C:$C,$A14,'Stock Movements'!$F:$F,C$2,'Stock Movements'!$D:$D,"Out") -> 0 | D14: =SUMIFS('Stock Movements'!$E:$E,'Stock Movements'!$C:$C,$A14,'Stock Movements'!$F:$F,D$2,'Stock Movements'!$D:$D,"Out") -> 0 | E14: =SUMIFS('Stock Movements'!$E:$E,'Stock Movements'!$C:$C,$A14,'Stock Movements'!$F:$F,E$2,'Stock Movements'!$D:$D,"Out") -> 0 | F14: =SUMIFS('Stock Movements'!$E:$E,'Stock Movements'!$C:$C,$A14,'Stock Movements'!$F:$F,F$2,'Stock Movements'!$D:$D,"Out") -> 0 | G14: =SUMIFS('Stock Movements'!$E:$E,'Stock Movements'!$C:$C,$A14,'Stock Movements'!$F:$F,G$2,'Stock Movements'!$D:$D,"Out") -> 0 | H14: =SUMIFS('Stock Movements'!$E:$E,'Stock Movements'!$C:$C,$A14,'Stock Movements'!$F:$F,H$2,'Stock Movements'!$D:$D,"Out") -> 0 | I14: =SUMIFS('Stock Movements'!$E:$E,'Stock Movements'!$C:$C,$A14,'Stock Movements'!$F:$F,I$2,'Stock Movements'!$D:$D,"Out") -> 0 | J14: =SUMIFS('Stock Movements'!$E:$E,'Stock Movements'!$C:$C,$A14,'Stock Movements'!$F:$F,J$2,'Stock Movements'!$D:$D,"Out") -> 0 | ... R14: =SUMIFS('Stock Movements'!$E:$E,'Stock Movements'!$C:$C,$A14,'Stock Movements'!$F:$F,R$2,'Stock Movements'!$D:$D,"Out") -> 0 | S14: =SUM(C14:R14) -> 0 | T14: =S14-'Item Catalog'!$M$14 -> 0
A15: ='Item Catalog'!$B$15 -> ITM-013 · BIG CAP SEAL FOR SLIM GENERIC | B15: ='Item Catalog'!$C$15 -> BIG CAP SEAL FOR SLIM GENERIC | C15: =SUMIFS('Stock Movements'!$E:$E,'Stock Movements'!$C:$C,$A15,'Stock Movements'!$F:$F,C$2,'Stock Movements'!$D:$D,"Out") -> 0 | D15: =SUMIFS('Stock Movements'!$E:$E,'Stock Movements'!$C:$C,$A15,'Stock Movements'!$F:$F,D$2,'Stock Movements'!$D:$D,"Out") -> 5 | E15: =SUMIFS('Stock Movements'!$E:$E,'Stock Movements'!$C:$C,$A15,'Stock Movements'!$F:$F,E$2,'Stock Movements'!$D:$D,"Out") -> 0 | F15: =SUMIFS('Stock Movements'!$E:$E,'Stock Movements'!$C:$C,$A15,'Stock Movements'!$F:$F,F$2,'Stock Movements'!$D:$D,"Out") -> 0 | G15: =SUMIFS('Stock Movements'!$E:$E,'Stock Movements'!$C:$C,$A15,'Stock Movements'!$F:$F,G$2,'Stock Movements'!$D:$D,"Out") -> 11 | H15: =SUMIFS('Stock Movements'!$E:$E,'Stock Movements'!$C:$C,$A15,'Stock Movements'!$F:$F,H$2,'Stock Movements'!$D:$D,"Out") -> 3 | I15: =SUMIFS('Stock Movements'!$E:$E,'Stock Movements'!$C:$C,$A15,'Stock Movements'!$F:$F,I$2,'Stock Movements'!$D:$D,"Out") -> 0 | J15: =SUMIFS('Stock Movements'!$E:$E,'Stock Movements'!$C:$C,$A15,'Stock Movements'!$F:$F,J$2,'Stock Movements'!$D:$D,"Out") -> 5 | ... R15: =SUMIFS('Stock Movements'!$E:$E,'Stock Movements'!$C:$C,$A15,'Stock Movements'!$F:$F,R$2,'Stock Movements'!$D:$D,"Out") -> 5 | S15: =SUM(C15:R15) -> 100 | T15: =S15-'Item Catalog'!$M$15 -> 0
A16: ='Item Catalog'!$B$16 -> ITM-014 · SMALL CAP SEAL FOR SLIM GENERIC | B16: ='Item Catalog'!$C$16 -> SMALL CAP SEAL FOR SLIM GENERIC | C16: =SUMIFS('Stock Movements'!$E:$E,'Stock Movements'!$C:$C,$A16,'Stock Movements'!$F:$F,C$2,'Stock Movements'!$D:$D,"Out") -> 1 | D16: =SUMIFS('Stock Movements'!$E:$E,'Stock Movements'!$C:$C,$A16,'Stock Movements'!$F:$F,D$2,'Stock Movements'!$D:$D,"Out") -> 1 | E16: =SUMIFS('Stock Movements'!$E:$E,'Stock Movements'!$C:$C,$A16,'Stock Movements'!$F:$F,E$2,'Stock Movements'!$D:$D,"Out") -> 0 | F16: =SUMIFS('Stock Movements'!$E:$E,'Stock Movements'!$C:$C,$A16,'Stock Movements'!$F:$F,F$2,'Stock Movements'!$D:$D,"Out") -> 0 | G16: =SUMIFS('Stock Movements'!$E:$E,'Stock Movements'!$C:$C,$A16,'Stock Movements'!$F:$F,G$2,'Stock Movements'!$D:$D,"Out") -> 4 | H16: =SUMIFS('Stock Movements'!$E:$E,'Stock Movements'!$C:$C,$A16,'Stock Movements'!$F:$F,H$2,'Stock Movements'!$D:$D,"Out") -> 1 | I16: =SUMIFS('Stock Movements'!$E:$E,'Stock Movements'!$C:$C,$A16,'Stock Movements'!$F:$F,I$2,'Stock Movements'!$D:$D,"Out") -> 0 | J16: =SUMIFS('Stock Movements'!$E:$E,'Stock Movements'!$C:$C,$A16,'Stock Movements'!$F:$F,J$2,'Stock Movements'!$D:$D,"Out") -> 0 | ... R16: =SUMIFS('Stock Movements'!$E:$E,'Stock Movements'!$C:$C,$A16,'Stock Movements'!$F:$F,R$2,'Stock Movements'!$D:$D,"Out") -> 0 | S16: =SUM(C16:R16) -> 36 | T16: =S16-'Item Catalog'!$M$16 -> 0
A17: ='Item Catalog'!$B$17 -> ITM-015 · FAUCET SEAL FOR SLIM GENERIC | B17: ='Item Catalog'!$C$17 -> FAUCET SEAL FOR SLIM GENERIC | C17: =SUMIFS('Stock Movements'!$E:$E,'Stock Movements'!$C:$C,$A17,'Stock Movements'!$F:$F,C$2,'Stock Movements'!$D:$D,"Out") -> 2 | D17: =SUMIFS('Stock Movements'!$E:$E,'Stock Movements'!$C:$C,$A17,'Stock Movements'!$F:$F,D$2,'Stock Movements'!$D:$D,"Out") -> 1 | E17: =SUMIFS('Stock Movements'!$E:$E,'Stock Movements'!$C:$C,$A17,'Stock Movements'!$F:$F,E$2,'Stock Movements'!$D:$D,"Out") -> 0 | F17: =SUMIFS('Stock Movements'!$E:$E,'Stock Movements'!$C:$C,$A17,'Stock Movements'!$F:$F,F$2,'Stock Movements'!$D:$D,"Out") -> 0 | G17: =SUMIFS('Stock Movements'!$E:$E,'Stock Movements'!$C:$C,$A17,'Stock Movements'!$F:$F,G$2,'Stock Movements'!$D:$D,"Out") -> 28 | H17: =SUMIFS('Stock Movements'!$E:$E,'Stock Movements'!$C:$C,$A17,'Stock Movements'!$F:$F,H$2,'Stock Movements'!$D:$D,"Out") -> 2 | I17: =SUMIFS('Stock Movements'!$E:$E,'Stock Movements'!$C:$C,$A17,'Stock Movements'!$F:$F,I$2,'Stock Movements'!$D:$D,"Out") -> 0 | J17: =SUMIFS('Stock Movements'!$E:$E,'Stock Movements'!$C:$C,$A17,'Stock Movements'!$F:$F,J$2,'Stock Movements'!$D:$D,"Out") -> 0 | ... R17: =SUMIFS('Stock Movements'!$E:$E,'Stock Movements'!$C:$C,$A17,'Stock Movements'!$F:$F,R$2,'Stock Movements'!$D:$D,"Out") -> 5 | S17: =SUM(C17:R17) -> 100 | T17: =S17-'Item Catalog'!$M$17 -> 0
A18: ='Item Catalog'!$B$18 -> ITM-016 · FAUCET SEAL FOR SLIM GENERIC | B18: ='Item Catalog'!$C$18 -> FAUCET SEAL FOR SLIM GENERIC | C18: =SUMIFS('Stock Movements'!$E:$E,'Stock Movements'!$C:$C,$A18,'Stock Movements'!$F:$F,C$2,'Stock Movements'!$D:$D,"Out") -> 0 | D18: =SUMIFS('Stock Movements'!$E:$E,'Stock Movements'!$C:$C,$A18,'Stock Movements'!$F:$F,D$2,'Stock Movements'!$D:$D,"Out") -> 0 | E18: =SUMIFS('Stock Movements'!$E:$E,'Stock Movements'!$C:$C,$A18,'Stock Movements'!$F:$F,E$2,'Stock Movements'!$D:$D,"Out") -> 0 | F18: =SUMIFS('Stock Movements'!$E:$E,'Stock Movements'!$C:$C,$A18,'Stock Movements'!$F:$F,F$2,'Stock Movements'!$D:$D,"Out") -> 0 | G18: =SUMIFS('Stock Movements'!$E:$E,'Stock Movements'!$C:$C,$A18,'Stock Movements'!$F:$F,G$2,'Stock Movements'!$D:$D,"Out") -> 0 | H18: =SUMIFS('Stock Movements'!$E:$E,'Stock Movements'!$C:$C,$A18,'Stock Movements'!$F:$F,H$2,'Stock Movements'!$D:$D,"Out") -> 0 | I18: =SUMIFS('Stock Movements'!$E:$E,'Stock Movements'!$C:$C,$A18,'Stock Movements'!$F:$F,I$2,'Stock Movements'!$D:$D,"Out") -> 0 | J18: =SUMIFS('Stock Movements'!$E:$E,'Stock Movements'!$C:$C,$A18,'Stock Movements'!$F:$F,J$2,'Stock Movements'!$D:$D,"Out") -> 0 | ... R18: =SUMIFS('Stock Movements'!$E:$E,'Stock Movements'!$C:$C,$A18,'Stock Movements'!$F:$F,R$2,'Stock Movements'!$D:$D,"Out") -> 0 | S18: =SUM(C18:R18) -> 11 | T18: =S18-'Item Catalog'!$M$18 -> 0
A19: ='Item Catalog'!$B$19 -> ITM-017 · UMBRELLA SEAL FOR ROUND GENERIC | B19: ='Item Catalog'!$C$19 -> UMBRELLA SEAL FOR ROUND GENERIC | C19: =SUMIFS('Stock Movements'!$E:$E,'Stock Movements'!$C:$C,$A19,'Stock Movements'!$F:$F,C$2,'Stock Movements'!$D:$D,"Out") -> 0 | D19: =SUMIFS('Stock Movements'!$E:$E,'Stock Movements'!$C:$C,$A19,'Stock Movements'!$F:$F,D$2,'Stock Movements'!$D:$D,"Out") -> 4 | E19: =SUMIFS('Stock Movements'!$E:$E,'Stock Movements'!$C:$C,$A19,'Stock Movements'!$F:$F,E$2,'Stock Movements'!$D:$D,"Out") -> 0 | F19: =SUMIFS('Stock Movements'!$E:$E,'Stock Movements'!$C:$C,$A19,'Stock Movements'!$F:$F,F$2,'Stock Movements'!$D:$D,"Out") -> 0 | G19: =SUMIFS('Stock Movements'!$E:$E,'Stock Movements'!$C:$C,$A19,'Stock Movements'!$F:$F,G$2,'Stock Movements'!$D:$D,"Out") -> 3 | H19: =SUMIFS('Stock Movements'!$E:$E,'Stock Movements'!$C:$C,$A19,'Stock Movements'!$F:$F,H$2,'Stock Movements'!$D:$D,"Out") -> 3 | I19: =SUMIFS('Stock Movements'!$E:$E,'Stock Movements'!$C:$C,$A19,'Stock Movements'!$F:$F,I$2,'Stock Movements'!$D:$D,"Out") -> 0 | J19: =SUMIFS('Stock Movements'!$E:$E,'Stock Movements'!$C:$C,$A19,'Stock Movements'!$F:$F,J$2,'Stock Movements'!$D:$D,"Out") -> 0 | ... R19: =SUMIFS('Stock Movements'!$E:$E,'Stock Movements'!$C:$C,$A19,'Stock Movements'!$F:$F,R$2,'Stock Movements'!$D:$D,"Out") -> 0 | S19: =SUM(C19:R19) -> 75 | T19: =S19-'Item Catalog'!$M$19 -> 0
A20: ='Item Catalog'!$B$20 -> ITM-018 · 1 L SOAP SANITIZER | B20: ='Item Catalog'!$C$20 -> 1 L SOAP SANITIZER | C20: =SUMIFS('Stock Movements'!$E:$E,'Stock Movements'!$C:$C,$A20,'Stock Movements'!$F:$F,C$2,'Stock Movements'!$D:$D,"Out") -> 21 | D20: =SUMIFS('Stock Movements'!$E:$E,'Stock Movements'!$C:$C,$A20,'Stock Movements'!$F:$F,D$2,'Stock Movements'!$D:$D,"Out") -> 0 | E20: =SUMIFS('Stock Movements'!$E:$E,'Stock Movements'!$C:$C,$A20,'Stock Movements'!$F:$F,E$2,'Stock Movements'!$D:$D,"Out") -> 0 | F20: =SUMIFS('Stock Movements'!$E:$E,'Stock Movements'!$C:$C,$A20,'Stock Movements'!$F:$F,F$2,'Stock Movements'!$D:$D,"Out") -> 0 | G20: =SUMIFS('Stock Movements'!$E:$E,'Stock Movements'!$C:$C,$A20,'Stock Movements'!$F:$F,G$2,'Stock Movements'!$D:$D,"Out") -> 0 | H20: =SUMIFS('Stock Movements'!$E:$E,'Stock Movements'!$C:$C,$A20,'Stock Movements'!$F:$F,H$2,'Stock Movements'!$D:$D,"Out") -> 0 | I20: =SUMIFS('Stock Movements'!$E:$E,'Stock Movements'!$C:$C,$A20,'Stock Movements'!$F:$F,I$2,'Stock Movements'!$D:$D,"Out") -> 0 | J20: =SUMIFS('Stock Movements'!$E:$E,'Stock Movements'!$C:$C,$A20,'Stock Movements'!$F:$F,J$2,'Stock Movements'!$D:$D,"Out") -> 3 | ... R20: =SUMIFS('Stock Movements'!$E:$E,'Stock Movements'!$C:$C,$A20,'Stock Movements'!$F:$F,R$2,'Stock Movements'!$D:$D,"Out") -> 6 | S20: =SUM(C20:R20) -> 35 | T20: =S20-'Item Catalog'!$M$20 -> 0
